Workbook

Sheet Inputs
A1: WHOLESALE SCALING MODEL — Here & There
A2: Every blue cell is yours to change. Yellow = assumption with no source data behind it. Black = formula, don't type over it.
A4: HOW TO USE
A5: 1. Set the three volume scenarios in B7:B9, then pick the active one in B11 (dropdown).
A6: 2. Set wholesale % of MSRP in B14. MSRPs live on the Items tab.
A7: Bear — units/day per item | B7: 7 | C7: your bear case
A8: Base — units/day per item | B8: 10 | C8: your base case
A9: Bull — units/day per item | B9: 15 | C9: your bull case
A10: VOLUME SCENARIOS (units sold per day, per item)
A11: ACTIVE SCENARIO | B11: Base
A12: Units/day per item (active) | B12: =IF($B$11="Bear",$B$7,IF($B$11="Bull",$B$9,$B$8))
A13: PRICING
A14: Wholesale price as % of MSRP | B14: 0.5 | C14: your instruction: wholesale at 50%
A16: COST BASIS
A17: Flat cost per unit (your $1 assumption) | B17: 1
A18: Cost basis | B18: Flat | C18: Flat = your $1.00 · Computed = real recipe + consumables
A19: Computed materials + consumables / unit | B19: =CostStack!$D$83 | D19: Excludes labor and kitchen time — those are costed by the hour in Scaling, so there is no double-count either way you set B18.
A20: Cost per unit in use | B20: =IF($B$18="Computed",$B$19,$B$17)
A21: Include labor + kitchen time cost? | B21: Yes | C21: No = you absorb your own time and already pay the kitchen anyway
A22: Wholesale accounts (stores) | B22: 1 | C22: Here & There = 1 today | D22: Units/day figures above are PER ITEM, PER ACCOUNT. More accounts fill the same batches; more SKUs at one account do not.
A23: LABOR AND BAKE CONSTANTS (from the Kairos app — real, not assumed)
A24: Batch yield (units per batch) | B24: 20 | C24: BATCH_YIELD, data-entry-app/index.html
A25: Setup (min, once per bake session) | B25: 20 | C25: SETUP_MIN
A26: Prep per batch (min) | B26: 15 | C26: PREP_MIN
A27: Bake per batch (min) | B27: 14 | C27: BAKE_MIN — single oven, glaze overlaps the bake
A28: Labor wage ($/hour, loaded) | B28: 30 | C28: your figure
A29: Commercial kitchen ($/hour) | B29: 50 | C29: your figure — charged on bake time, not per unit
A30: Combined time cost ($/hour) | B30: =$B$28+$B$29
A31: Setup treatment | B31: Shared | C31: Per item = each SKU gets its own session. Shared = all SKUs in one session.
A32: Bake sessions per week | B32: 3 | D32: THE BIGGEST LEVER. Baking 7x/week means tiny half-empty batches; 2-3x/week fills them and divides the setup across far more units.
A33: CALENDAR
A34: Operating days per week | B34: 7
A35: Days per year | B35: =$B$34*52
A36: Days per month | B36: =$B$35/12
A38: REALITY CHECKS (measured, for context — these do not feed the model)
A39: Madeleine retail price observed | B39: 4.5 | C39: median of 76 single-madeleine LM receipts
A40: App's stored madeleine price | B40: 2.5 | C40: push_store_stats.py PRICE — equals 50% of a $5 MSRP
A41: LM madeleines/day, Aug 1-7 | B41: 8.7 | C41: Store Sales tab
A42: LM store transactions/day, Aug 1-7 | B42: 233 | C42: Store Sales tab

Sheet Items
A1: ITEMS
A2: MSRPs are yours. Wholesale = MSRP x Inputs!B14. Override a single item's cost in column E; leave blank to use the global basis.
A4: # | B4: Item | C4: MSRP | D4: Wholesale $ | E4: Cost override | F4: Cost used $/unit | G4: Margin $/unit | H4: Margin % | I4: Cum. wholesale $ | J4: Cum. cost $
A5: 1 | B5: Item 1 | C5: 5 | D5: =$C5*Inputs!$B$14 | F5: =IF(ISNUMBER($E5),$E5,Inputs!$B$20) | G5: =$D5-$F5 | H5: =IFERROR($G5/$D5,0) | I5: =SUM($D$5:$D5) | J5: =SUM($F$5:$F5)
A6: 2 | B6: Item 2 | C6: 7 | D6: =$C6*Inputs!$B$14 | F6: =IF(ISNUMBER($E6),$E6,Inputs!$B$20) | G6: =$D6-$F6 | H6: =IFERROR($G6/$D6,0) | I6: =SUM($D$5:$D6) | J6: =SUM($F$5:$F6)
A7: 3 | B7: Item 3 | C7: 6 | D7: =$C7*Inputs!$B$14 | F7: =IF(ISNUMBER($E7),$E7,Inputs!$B$20) | G7: =$D7-$F7 | H7: =IFERROR($G7/$D7,0) | I7: =SUM($D$5:$D7) | J7: =SUM($F$5:$F7)
A8: 4 | B8: Item 4 | C8: 5 | D8: =$C8*Inputs!$B$14 | F8: =IF(ISNUMBER($E8),$E8,Inputs!$B$20) | G8: =$D8-$F8 | H8: =IFERROR($G8/$D8,0) | I8: =SUM($D$5:$D8) | J8: =SUM($F$5:$F8)
A9: 5 | B9: Item 5 | C9: 5 | D9: =$C9*Inputs!$B$14 | F9: =IF(ISNUMBER($E9),$E9,Inputs!$B$20) | G9: =$D9-$F9 | H9: =IFERROR($G9/$D9,0) | I9: =SUM($D$5:$D9) | J9: =SUM($F$5:$F9)
B11: TOTAL / all 5 | C11: =SUM($C$5:$C$9) | D11: =SUM($D$5:$D$9) | F11: =SUM($F$5:$F$9) | G11: =SUM($G$5:$G$9) | H11: =IFERROR($G$11/$D$11,0)
A13: MSRPs supplied by you: item 1 $5, item 2 $7, item 3 $6, item 4 $5, item 5 $5.
A14: Rename the items in column B — the model does not care what they are called.

Sheet Scaling
A1: SCALING 1 → 5 ITEMS
A2: Weekly basis, because you bake in sessions, not continuously. Revenue scales linearly with items; bake time does not. That gap is the whole story.
A3: =" Scenario: "&Inputs!$B$11&" · "&TEXT(Inputs!$B$12,"0.0")&" units/day/item · "&TEXT(Inputs!$B$32,"0")&" bake sessions/week · setup "&Inputs!$B$31&" · cost basis "&Inputs!$B$18
A5: Items sold | B5: Units/week | C5: Units per session, per item | D5: Batches per session, per item | E5: Bake hrs/week | F5: Revenue/week | G5: Materials/week | H5: Labor+kitchen/week | I5: Profit/week | J5: Profit/day | K5: Profit/year | L5: Incremental /yr
A6: 1 item | B6: =1*Inputs!$B$22*Inputs!$B$12*7 | C6: =Inputs!$B$22*Inputs!$B$12*7/Inputs!$B$32 | D6: =ROUNDUP(Inputs!$B$22*Inputs!$B$12*7/Inputs!$B$32/Inputs!$B$24,0) | E6: =IF(Inputs!$B$31="Shared",Inputs!$B$32*(Inputs!$B$25+1*ROUNDUP(Inputs!$B$22*Inputs!$B$12*7/Inputs!$B$32/Inputs!$B$24,0)*(Inputs!$B$26+Inputs!$B$27))/60,Inputs!$B$32*1*(Inputs!$B$25+ROUNDUP(Inputs!$B$22*Inputs!$B$12*7/Inputs!$B$32/Inputs!$B$24,0)*(Inputs!$B$26+Inputs!$B$27))/60) | F6: =Inputs!$B$22*Inputs!$B$12*7*INDEX(Items!$I$5:$I$9,1) | G6: =Inputs!$B$22*Inputs!$B$12*7*INDEX(Items!$J$5:$J$9,1) | H6: =IF(Inputs!$B$21="Yes",$E6*Inputs!$B$30,0) | I6: =$F6-$G6-$H6 | J6: =$I6/7 | K6: =$I6*52 | L6: -
A7: 2 items | B7: =2*Inputs!$B$22*Inputs!$B$12*7 | C7: =Inputs!$B$22*Inputs!$B$12*7/Inputs!$B$32 | D7: =ROUNDUP(Inputs!$B$22*Inputs!$B$12*7/Inputs!$B$32/Inputs!$B$24,0) | E7: =IF(Inputs!$B$31="Shared",Inputs!$B$32*(Inputs!$B$25+2*ROUNDUP(Inputs!$B$22*Inputs!$B$12*7/Inputs!$B$32/Inputs!$B$24,0)*(Inputs!$B$26+Inputs!$B$27))/60,Inputs!$B$32*2*(Inputs!$B$25+ROUNDUP(Inputs!$B$22*Inputs!$B$12*7/Inputs!$B$32/Inputs!$B$24,0)*(Inputs!$B$26+Inputs!$B$27))/60) | F7: =Inputs!$B$22*Inputs!$B$12*7*INDEX(Items!$I$5:$I$9,2) | G7: =Inputs!$B$22*Inputs!$B$12*7*INDEX(Items!$J$5:$J$9,2) | H7: =IF(Inputs!$B$21="Yes",$E7*Inputs!$B$30,0) | I7: =$F7-$G7-$H7 | J7: =$I7/7 | K7: =$I7*52 | L7: =$K7-$K6
A8: 3 items | B8: =3*Inputs!$B$22*Inputs!$B$12*7 | C8: =Inputs!$B$22*Inputs!$B$12*7/Inputs!$B$32 | D8: =ROUNDUP(Inputs!$B$22*Inputs!$B$12*7/Inputs!$B$32/Inputs!$B$24,0) | E8: =IF(Inputs!$B$31="Shared",Inputs!$B$32*(Inputs!$B$25+3*ROUNDUP(Inputs!$B$22*Inputs!$B$12*7/Inputs!$B$32/Inputs!$B$24,0)*(Inputs!$B$26+Inputs!$B$27))/60,Inputs!$B$32*3*(Inputs!$B$25+ROUNDUP(Inputs!$B$22*Inputs!$B$12*7/Inputs!$B$32/Inputs!$B$24,0)*(Inputs!$B$26+Inputs!$B$27))/60) | F8: =Inputs!$B$22*Inputs!$B$12*7*INDEX(Items!$I$5:$I$9,3) | G8: =Inputs!$B$22*Inputs!$B$12*7*INDEX(Items!$J$5:$J$9,3) | H8: =IF(Inputs!$B$21="Yes",$E8*Inputs!$B$30,0) | I8: =$F8-$G8-$H8 | J8: =$I8/7 | K8: =$I8*52 | L8: =$K8-$K7
A9: 4 items | B9: =4*Inputs!$B$22*Inputs!$B$12*7 | C9: =Inputs!$B$22*Inputs!$B$12*7/Inputs!$B$32 | D9: =ROUNDUP(Inputs!$B$22*Inputs!$B$12*7/Inputs!$B$32/Inputs!$B$24,0) | E9: =IF(Inputs!$B$31="Shared",Inputs!$B$32*(Inputs!$B$25+4*ROUNDUP(Inputs!$B$22*Inputs!$B$12*7/Inputs!$B$32/Inputs!$B$24,0)*(Inputs!$B$26+Inputs!$B$27))/60,Inputs!$B$32*4*(Inputs!$B$25+ROUNDUP(Inputs!$B$22*Inputs!$B$12*7/Inputs!$B$32/Inputs!$B$24,0)*(Inputs!$B$26+Inputs!$B$27))/60) | F9: =Inputs!$B$22*Inputs!$B$12*7*INDEX(Items!$I$5:$I$9,4) | G9: =Inputs!$B$22*Inputs!$B$12*7*INDEX(Items!$J$5:$J$9,4) | H9: =IF(Inputs!$B$21="Yes",$E9*Inputs!$B$30,0) | I9: =$F9-$G9-$H9 | J9: =$I9/7 | K9: =$I9*52 | L9: =$K9-$K8
A10: 5 items | B10: =5*Inputs!$B$22*Inputs!$B$12*7 | C10: =Inputs!$B$22*Inputs!$B$12*7/Inputs!$B$32 | D10: =ROUNDUP(Inputs!$B$22*Inputs!$B$12*7/Inputs!$B$32/Inputs!$B$24,0) | E10: =IF(Inputs!$B$31="Shared",Inputs!$B$32*(Inputs!$B$25+5*ROUNDUP(Inputs!$B$22*Inputs!$B$12*7/Inputs!$B$32/Inputs!$B$24,0)*(Inputs!$B$26+Inputs!$B$27))/60,Inputs!$B$32*5*(Inputs!$B$25+ROUNDUP(Inputs!$B$22*Inputs!$B$12*7/Inputs!$B$32/Inputs!$B$24,0)*(Inputs!$B$26+Inputs!$B$27))/60) | F10: =Inputs!$B$22*Inputs!$B$12*7*INDEX(Items!$I$5:$I$9,5) | G10: =Inputs!$B$22*Inputs!$B$12*7*INDEX(Items!$J$5:$J$9,5) | H10: =IF(Inputs!$B$21="Yes",$E10*Inputs!$B$30,0) | I10: =$F10-$G10-$H10 | J10: =$I10/7 | K10: =$I10*52 | L10: =$K10-$K9
A12: PER-UNIT AND PER-HOUR VIEW
A13: Items sold | B13: Profit $/unit | C13: Profit $/bake hr | D13: Bake min/unit | E13: Time cost $/unit | F13: Materials $/unit | G13: Margin % of wholesale
A14: 1 item | B14: =IFERROR($I6/$B6,0) | C14: =IFERROR($I6/$E6,0) | D14: =IFERROR($E6*60/$B6,0) | E14: =IFERROR($H6/$B6,0) | F14: =IFERROR($G6/$B6,0) | G14: =IFERROR($I6/$F6,0)
A15: 2 items | B15: =IFERROR($I7/$B7,0) | C15: =IFERROR($I7/$E7,0) | D15: =IFERROR($E7*60/$B7,0) | E15: =IFERROR($H7/$B7,0) | F15: =IFERROR($G7/$B7,0) | G15: =IFERROR($I7/$F7,0)
A16: 3 items | B16: =IFERROR($I8/$B8,0) | C16: =IFERROR($I8/$E8,0) | D16: =IFERROR($E8*60/$B8,0) | E16: =IFERROR($H8/$B8,0) | F16: =IFERROR($G8/$B8,0) | G16: =IFERROR($I8/$F8,0)
A17: 4 items | B17: =IFERROR($I9/$B9,0) | C17: =IFERROR($I9/$E9,0) | D17: =IFERROR($E9*60/$B9,0) | E17: =IFERROR($H9/$B9,0) | F17: =IFERROR($G9/$B9,0) | G17: =IFERROR($I9/$F9,0)
A18: 5 items | B18: =IFERROR($I10/$B10,0) | C18: =IFERROR($I10/$E10,0) | D18: =IFERROR($E10*60/$B10,0) | E18: =IFERROR($H10/$B10,0) | F18: =IFERROR($G10/$B10,0) | G18: =IFERROR($I10/$F10,0)
A20: THE THREE LEVERS, IN ORDER OF POWER
A21: 1. Bake sessions per week (Inputs!B32). Fewer, bigger sessions fill the 20-unit batches and pay the 20-min setup once instead of seven times.
A22: 2. Setup treatment (Inputs!B31). "Shared" bakes all five SKUs in one session — one setup for the lot, not five.
A23: 3. Batch yield (Inputs!B24). Bigger trays divide the 29 min of prep+bake across more units. See the BreakEven tab, section D.
A24: Adding SKUs raises revenue in a straight line. Whether it raises PROFIT depends entirely on whether the new SKU rides an existing session or forces a new one.

Sheet Scenarios
A1: BEAR / BASE / BULL
A2: All three volume cases at once, on the same weekly basis. Each block reads its own units/day from Inputs.
A4: BEAR — units/day per item = Inputs!$B$7
A5: Items sold | B5: Units/week | C5: Bake hrs/week | D5: Revenue/week | E5: Materials/week | F5: Labor+kitchen/week | G5: Profit/week | H5: Profit/day | I5: Profit/year
A6: 1 item | B6: =1*Inputs!$B$22*Inputs!$B$7*7 | C6: =IF(Inputs!$B$31="Shared",Inputs!$B$32*(Inputs!$B$25+1*ROUNDUP(Inputs!$B$22*Inputs!$B$7*7/Inputs!$B$32/Inputs!$B$24,0)*(Inputs!$B$26+Inputs!$B$27))/60,Inputs!$B$32*1*(Inputs!$B$25+ROUNDUP(Inputs!$B$22*Inputs!$B$7*7/Inputs!$B$32/Inputs!$B$24,0)*(Inputs!$B$26+Inputs!$B$27))/60) | D6: =Inputs!$B$22*Inputs!$B$7*7*INDEX(Items!$I$5:$I$9,1) | E6: =Inputs!$B$22*Inputs!$B$7*7*INDEX(Items!$J$5:$J$9,1) | F6: =IF(Inputs!$B$21="Yes",$C6*Inputs!$B$30,0) | G6: =$D6-$E6-$F6 | H6: =$G6/7 | I6: =$G6*52
A7: 2 items | B7: =2*Inputs!$B$22*Inputs!$B$7*7 | C7: =IF(Inputs!$B$31="Shared",Inputs!$B$32*(Inputs!$B$25+2*ROUNDUP(Inputs!$B$22*Inputs!$B$7*7/Inputs!$B$32/Inputs!$B$24,0)*(Inputs!$B$26+Inputs!$B$27))/60,Inputs!$B$32*2*(Inputs!$B$25+ROUNDUP(Inputs!$B$22*Inputs!$B$7*7/Inputs!$B$32/Inputs!$B$24,0)*(Inputs!$B$26+Inputs!$B$27))/60) | D7: =Inputs!$B$22*Inputs!$B$7*7*INDEX(Items!$I$5:$I$9,2) | E7: =Inputs!$B$22*Inputs!$B$7*7*INDEX(Items!$J$5:$J$9,2) | F7: =IF(Inputs!$B$21="Yes",$C7*Inputs!$B$30,0) | G7: =$D7-$E7-$F7 | H7: =$G7/7 | I7: =$G7*52
A8: 3 items | B8: =3*Inputs!$B$22*Inputs!$B$7*7 | C8: =IF(Inputs!$B$31="Shared",Inputs!$B$32*(Inputs!$B$25+3*ROUNDUP(Inputs!$B$22*Inputs!$B$7*7/Inputs!$B$32/Inputs!$B$24,0)*(Inputs!$B$26+Inputs!$B$27))/60,Inputs!$B$32*3*(Inputs!$B$25+ROUNDUP(Inputs!$B$22*Inputs!$B$7*7/Inputs!$B$32/Inputs!$B$24,0)*(Inputs!$B$26+Inputs!$B$27))/60) | D8: =Inputs!$B$22*Inputs!$B$7*7*INDEX(Items!$I$5:$I$9,3) | E8: =Inputs!$B$22*Inputs!$B$7*7*INDEX(Items!$J$5:$J$9,3) | F8: =IF(Inputs!$B$21="Yes",$C8*Inputs!$B$30,0) | G8: =$D8-$E8-$F8 | H8: =$G8/7 | I8: =$G8*52
A9: 4 items | B9: =4*Inputs!$B$22*Inputs!$B$7*7 | C9: =IF(Inputs!$B$31="Shared",Inputs!$B$32*(Inputs!$B$25+4*ROUNDUP(Inputs!$B$22*Inputs!$B$7*7/Inputs!$B$32/Inputs!$B$24,0)*(Inputs!$B$26+Inputs!$B$27))/60,Inputs!$B$32*4*(Inputs!$B$25+ROUNDUP(Inputs!$B$22*Inputs!$B$7*7/Inputs!$B$32/Inputs!$B$24,0)*(Inputs!$B$26+Inputs!$B$27))/60) | D9: =Inputs!$B$22*Inputs!$B$7*7*INDEX(Items!$I$5:$I$9,4) | E9: =Inputs!$B$22*Inputs!$B$7*7*INDEX(Items!$J$5:$J$9,4) | F9: =IF(Inputs!$B$21="Yes",$C9*Inputs!$B$30,0) | G9: =$D9-$E9-$F9 | H9: =$G9/7 | I9: =$G9*52
A10: 5 items | B10: =5*Inputs!$B$22*Inputs!$B$7*7 | C10: =IF(Inputs!$B$31="Shared",Inputs!$B$32*(Inputs!$B$25+5*ROUNDUP(Inputs!$B$22*Inputs!$B$7*7/Inputs!$B$32/Inputs!$B$24,0)*(Inputs!$B$26+Inputs!$B$27))/60,Inputs!$B$32*5*(Inputs!$B$25+ROUNDUP(Inputs!$B$22*Inputs!$B$7*7/Inputs!$B$32/Inputs!$B$24,0)*(Inputs!$B$26+Inputs!$B$27))/60) | D10: =Inputs!$B$22*Inputs!$B$7*7*INDEX(Items!$I$5:$I$9,5) | E10: =Inputs!$B$22*Inputs!$B$7*7*INDEX(Items!$J$5:$J$9,5) | F10: =IF(Inputs!$B$21="Yes",$C10*Inputs!$B$30,0) | G10: =$D10-$E10-$F10 | H10: =$G10/7 | I10: =$G10*52
A12: BASE — units/day per item = Inputs!$B$8
A13: Items sold | B13: Units/week | C13: Bake hrs/week | D13: Revenue/week | E13: Materials/week | F13: Labor+kitchen/week | G13: Profit/week | H13: Profit/day | I13: Profit/year
A14: 1 item | B14: =1*Inputs!$B$22*Inputs!$B$8*7 | C14: =IF(Inputs!$B$31="Shared",Inputs!$B$32*(Inputs!$B$25+1*ROUNDUP(Inputs!$B$22*Inputs!$B$8*7/Inputs!$B$32/Inputs!$B$24,0)*(Inputs!$B$26+Inputs!$B$27))/60,Inputs!$B$32*1*(Inputs!$B$25+ROUNDUP(Inputs!$B$22*Inputs!$B$8*7/Inputs!$B$32/Inputs!$B$24,0)*(Inputs!$B$26+Inputs!$B$27))/60) | D14: =Inputs!$B$22*Inputs!$B$8*7*INDEX(Items!$I$5:$I$9,1) | E14: =Inputs!$B$22*Inputs!$B$8*7*INDEX(Items!$J$5:$J$9,1) | F14: =IF(Inputs!$B$21="Yes",$C14*Inputs!$B$30,0) | G14: =$D14-$E14-$F14 | H14: =$G14/7 | I14: =$G14*52
A15: 2 items | B15: =2*Inputs!$B$22*Inputs!$B$8*7 | C15: =IF(Inputs!$B$31="Shared",Inputs!$B$32*(Inputs!$B$25+2*ROUNDUP(Inputs!$B$22*Inputs!$B$8*7/Inputs!$B$32/Inputs!$B$24,0)*(Inputs!$B$26+Inputs!$B$27))/60,Inputs!$B$32*2*(Inputs!$B$25+ROUNDUP(Inputs!$B$22*Inputs!$B$8*7/Inputs!$B$32/Inputs!$B$24,0)*(Inputs!$B$26+Inputs!$B$27))/60) | D15: =Inputs!$B$22*Inputs!$B$8*7*INDEX(Items!$I$5:$I$9,2) | E15: =Inputs!$B$22*Inputs!$B$8*7*INDEX(Items!$J$5:$J$9,2) | F15: =IF(Inputs!$B$21="Yes",$C15*Inputs!$B$30,0) | G15: =$D15-$E15-$F15 | H15: =$G15/7 | I15: =$G15*52
A16: 3 items | B16: =3*Inputs!$B$22*Inputs!$B$8*7 | C16: =IF(Inputs!$B$31="Shared",Inputs!$B$32*(Inputs!$B$25+3*ROUNDUP(Inputs!$B$22*Inputs!$B$8*7/Inputs!$B$32/Inputs!$B$24,0)*(Inputs!$B$26+Inputs!$B$27))/60,Inputs!$B$32*3*(Inputs!$B$25+ROUNDUP(Inputs!$B$22*Inputs!$B$8*7/Inputs!$B$32/Inputs!$B$24,0)*(Inputs!$B$26+Inputs!$B$27))/60) | D16: =Inputs!$B$22*Inputs!$B$8*7*INDEX(Items!$I$5:$I$9,3) | E16: =Inputs!$B$22*Inputs!$B$8*7*INDEX(Items!$J$5:$J$9,3) | F16: =IF(Inputs!$B$21="Yes",$C16*Inputs!$B$30,0) | G16: =$D16-$E16-$F16 | H16: =$G16/7 | I16: =$G16*52
A17: 4 items | B17: =4*Inputs!$B$22*Inputs!$B$8*7 | C17: =IF(Inputs!$B$31="Shared",Inputs!$B$32*(Inputs!$B$25+4*ROUNDUP(Inputs!$B$22*Inputs!$B$8*7/Inputs!$B$32/Inputs!$B$24,0)*(Inputs!$B$26+Inputs!$B$27))/60,Inputs!$B$32*4*(Inputs!$B$25+ROUNDUP(Inputs!$B$22*Inputs!$B$8*7/Inputs!$B$32/Inputs!$B$24,0)*(Inputs!$B$26+Inputs!$B$27))/60) | D17: =Inputs!$B$22*Inputs!$B$8*7*INDEX(Items!$I$5:$I$9,4) | E17: =Inputs!$B$22*Inputs!$B$8*7*INDEX(Items!$J$5:$J$9,4) | F17: =IF(Inputs!$B$21="Yes",$C17*Inputs!$B$30,0) | G17: =$D17-$E17-$F17 | H17: =$G17/7 | I17: =$G17*52
A18: 5 items | B18: =5*Inputs!$B$22*Inputs!$B$8*7 | C18: =IF(Inputs!$B$31="Shared",Inputs!$B$32*(Inputs!$B$25+5*ROUNDUP(Inputs!$B$22*Inputs!$B$8*7/Inputs!$B$32/Inputs!$B$24,0)*(Inputs!$B$26+Inputs!$B$27))/60,Inputs!$B$32*5*(Inputs!$B$25+ROUNDUP(Inputs!$B$22*Inputs!$B$8*7/Inputs!$B$32/Inputs!$B$24,0)*(Inputs!$B$26+Inputs!$B$27))/60) | D18: =Inputs!$B$22*Inputs!$B$8*7*INDEX(Items!$I$5:$I$9,5) | E18: =Inputs!$B$22*Inputs!$B$8*7*INDEX(Items!$J$5:$J$9,5) | F18: =IF(Inputs!$B$21="Yes",$C18*Inputs!$B$30,0) | G18: =$D18-$E18-$F18 | H18: =$G18/7 | I18: =$G18*52
A20: BULL — units/day per item = Inputs!$B$9
A21: Items sold | B21: Units/week | C21: Bake hrs/week | D21: Revenue/week | E21: Materials/week | F21: Labor+kitchen/week | G21: Profit/week | H21: Profit/day | I21: Profit/year
A22: 1 item | B22: =1*Inputs!$B$22*Inputs!$B$9*7 | C22: =IF(Inputs!$B$31="Shared",Inputs!$B$32*(Inputs!$B$25+1*ROUNDUP(Inputs!$B$22*Inputs!$B$9*7/Inputs!$B$32/Inputs!$B$24,0)*(Inputs!$B$26+Inputs!$B$27))/60,Inputs!$B$32*1*(Inputs!$B$25+ROUNDUP(Inputs!$B$22*Inputs!$B$9*7/Inputs!$B$32/Inputs!$B$24,0)*(Inputs!$B$26+Inputs!$B$27))/60) | D22: =Inputs!$B$22*Inputs!$B$9*7*INDEX(Items!$I$5:$I$9,1) | E22: =Inputs!$B$22*Inputs!$B$9*7*INDEX(Items!$J$5:$J$9,1) | F22: =IF(Inputs!$B$21="Yes",$C22*Inputs!$B$30,0) | G22: =$D22-$E22-$F22 | H22: =$G22/7 | I22: =$G22*52
A23: 2 items | B23: =2*Inputs!$B$22*Inputs!$B$9*7 | C23: =IF(Inputs!$B$31="Shared",Inputs!$B$32*(Inputs!$B$25+2*ROUNDUP(Inputs!$B$22*Inputs!$B$9*7/Inputs!$B$32/Inputs!$B$24,0)*(Inputs!$B$26+Inputs!$B$27))/60,Inputs!$B$32*2*(Inputs!$B$25+ROUNDUP(Inputs!$B$22*Inputs!$B$9*7/Inputs!$B$32/Inputs!$B$24,0)*(Inputs!$B$26+Inputs!$B$27))/60) | D23: =Inputs!$B$22*Inputs!$B$9*7*INDEX(Items!$I$5:$I$9,2) | E23: =Inputs!$B$22*Inputs!$B$9*7*INDEX(Items!$J$5:$J$9,2) | F23: =IF(Inputs!$B$21="Yes",$C23*Inputs!$B$30,0) | G23: =$D23-$E23-$F23 | H23: =$G23/7 | I23: =$G23*52
A24: 3 items | B24: =3*Inputs!$B$22*Inputs!$B$9*7 | C24: =IF(Inputs!$B$31="Shared",Inputs!$B$32*(Inputs!$B$25+3*ROUNDUP(Inputs!$B$22*Inputs!$B$9*7/Inputs!$B$32/Inputs!$B$24,0)*(Inputs!$B$26+Inputs!$B$27))/60,Inputs!$B$32*3*(Inputs!$B$25+ROUNDUP(Inputs!$B$22*Inputs!$B$9*7/Inputs!$B$32/Inputs!$B$24,0)*(Inputs!$B$26+Inputs!$B$27))/60) | D24: =Inputs!$B$22*Inputs!$B$9*7*INDEX(Items!$I$5:$I$9,3) | E24: =Inputs!$B$22*Inputs!$B$9*7*INDEX(Items!$J$5:$J$9,3) | F24: =IF(Inputs!$B$21="Yes",$C24*Inputs!$B$30,0) | G24: =$D24-$E24-$F24 | H24: =$G24/7 | I24: =$G24*52
A25: 4 items | B25: =4*Inputs!$B$22*Inputs!$B$9*7 | C25: =IF(Inputs!$B$31="Shared",Inputs!$B$32*(Inputs!$B$25+4*ROUNDUP(Inputs!$B$22*Inputs!$B$9*7/Inputs!$B$32/Inputs!$B$24,0)*(Inputs!$B$26+Inputs!$B$27))/60,Inputs!$B$32*4*(Inputs!$B$25+ROUNDUP(Inputs!$B$22*Inputs!$B$9*7/Inputs!$B$32/Inputs!$B$24,0)*(Inputs!$B$26+Inputs!$B$27))/60) | D25: =Inputs!$B$22*Inputs!$B$9*7*INDEX(Items!$I$5:$I$9,4) | E25: =Inputs!$B$22*Inputs!$B$9*7*INDEX(Items!$J$5:$J$9,4) | F25: =IF(Inputs!$B$21="Yes",$C25*Inputs!$B$30,0) | G25: =$D25-$E25-$F25 | H25: =$G25/7 | I25: =$G25*52
A26: 5 items | B26: =5*Inputs!$B$22*Inputs!$B$9*7 | C26: =IF(Inputs!$B$31="Shared",Inputs!$B$32*(Inputs!$B$25+5*ROUNDUP(Inputs!$B$22*Inputs!$B$9*7/Inputs!$B$32/Inputs!$B$24,0)*(Inputs!$B$26+Inputs!$B$27))/60,Inputs!$B$32*5*(Inputs!$B$25+ROUNDUP(Inputs!$B$22*Inputs!$B$9*7/Inputs!$B$32/Inputs!$B$24,0)*(Inputs!$B$26+Inputs!$B$27))/60) | D26: =Inputs!$B$22*Inputs!$B$9*7*INDEX(Items!$I$5:$I$9,5) | E26: =Inputs!$B$22*Inputs!$B$9*7*INDEX(Items!$J$5:$J$9,5) | F26: =IF(Inputs!$B$21="Yes",$C26*Inputs!$B$30,0) | G26: =$D26-$E26-$F26 | H26: =$G26/7 | I26: =$G26*52
A28: SUMMARY — annual profit at 5 items
A29: Bear | B29: =$I$10 | C29: =IFERROR($B29/$B30-1,0) | D29: vs base
A30: Base | B30: =$I$18
A31: Bull | B31: =$I$26 | C31: =IFERROR($B31/$B30-1,0) | D31: vs base

Sheet CostStack
A1: WHAT A MADELEINE ACTUALLY COSTS
A2: Recipes and ingredient prices are real, from kairos.html. Labor is derived from the app's bake constants. Everything else had NO source data and is an assumption — yellow.
A4: A · INGREDIENT PRICES (source: kairos.html DEFAULT_PRICES — Costco / Target / Amazon retail packs)
A5: Ingredient | B5: Pack size | C5: Unit | D5: Pack price | E5: $ per g/ml | F5: Note
A6: Cake Flour (AP proxy) | B6: 9071.8 | C6: g | D6: 19.99 | E6: =IFERROR($D6/$B6,0) | F6: Cake Flour is UNPRICED in source; AP flour used
A7: Baking Powder | B7: 1814.4 | C7: g | D7: 14.99 | E7: =IFERROR($D7/$B7,0) | F7: Costco Clabber Girl 4lb
A8: Salt | B8: 850.5 | C8: g | D8: 3.99 | E8: =IFERROR($D8/$B8,0) | F8: Costco Kirkland sea salt 30oz
A9: Eggs | B9: 3400 | C9: g | D9: 8.29 | E9: =IFERROR($D9/$B9,0) | F9: Costco Kirkland cage free 60ct
A10: Sugar | B10: 11340 | C10: g | D10: 20.19 | E10: =IFERROR($D10/$B10,0) | F10: Costco C&H 25lb
A11: Vanilla Extract | B11: 473 | C11: ml | D11: 10.87 | E11: =IFERROR($D11/$B11,0) | F11: Costco Kirkland 16oz
A12: Unsalted Butter | B12: 907.2 | C12: g | D12: 18.49 | E12: =IFERROR($D12/$B12,0) | F12: Kerrygold 8oz x4
A13: Powdered Sugar | B13: 907.2 | C13: g | D13: 3.89 | E13: =IFERROR($D13/$B13,0) | F13: glazes
A14: Lemon Juice | B14: 2000 | C14: ml | D14: 9.09 | E14: =IFERROR($D14/$B14,0) | F14: Lemon Poppy glaze
A15: Coconut Milk | B15: 400 | C15: ml | D15: 2.39 | E15: =IFERROR($D15/$B15,0) | F15: Ube glaze
A16: Ube Extract | B16: 60 | C16: ml | D16: 6.95 | E16: =IFERROR($D16/$B16,0) | F16: Ube
A17: Cream Cheese | B17: 1360.8 | C17: g | D17: 10.49 | E17: =IFERROR($D17/$B17,0) | F17: Dot Cake frosting
... A21: Cocoa Powder | B21: 700 | C21: g | D21: 14.99 | E21: =IFERROR($D21/$B21,0) | F21: Double Choco
A23: B · BASE BATTER, one batch (yields 20 madeleines) — everything except the flour
A24: Ingredient | B24: Grams / ml | D24: Cost
A25: Baking Powder | B25: 6 | D25: =$B25*$E$7 | F25: MAD_BASE in kairos.html. Yield 20 = BATCH_YIELD in the app.
A26: Salt | B26: 2 | D26: =$B26*$E$8
A27: Eggs | B27: 200 | D27: =$B27*$E$9
A28: Sugar | B28: 140 | D28: =$B28*$E$10
A29: Vanilla Extract | B29: 5 | D29: =$B29*$E$11
A30: Unsalted Butter | B30: 200 | D30: =$B30*$E$12
A31: Base ex-flour, per batch | D31: =SUM($D$25:$D$30)
A33: C · COST PER MADELEINE BY FLAVOR (ingredients only — no labor, no energy, no packaging)
A34: Flavor | B34: Flour g | C34: Flavoring $/batch | D34: Glaze $/batch | E34: Topping $/unit | F34: Ingredients $/unit
A35: Lemon Poppy | B35: 174 | C35: 0 | D35: =100*$E$13+25*$E$14+4*$E$12 | E35: 0 | F35: =($D$31+$B35*$E$6+$C35+$D35)/Inputs!$B$24+$E35
A36: Sea Salt / Classic | B36: 174 | C36: 0 | D36: 0 | E36: 0 | F36: =($D$31+$B36*$E$6+$C36+$D36)/Inputs!$B$24+$E36
A37: Ube | B37: 134 | C37: =2.5*$E$16 | D37: =100*$E$13+50*$E$15+1*$E$16 | E37: =($B$19/150)*$E$19 | F37: =($D$31+$B37*$E$6+$C37+$D37)/Inputs!$B$24+$E37
A38: Dot Cake | B38: 174 | C38: 0 | D38: 0 | E38: =(113/200)*$E$12+(225/200)*$E$17+(70/200)*$E$13+($B$18/100)*$E$18 | F38: =($D$31+$B38*$E$6+$C38+$D38)/Inputs!$B$24+$E38
A39: Matcha | B39: 156 | C39: =14*$E$20 | D39: 0 | E39: 0 | F39: =($D$31+$B39*$E$6+$C39+$D39)/Inputs!$B$24+$E39
A40: Double Choco | B40: 146 | C40: =28*$E$21 | D40: 0 | E40: 0 | F40: =($D$31+$B40*$E$6+$C40+$D40)/Inputs!$B$24+$E40
A41: Average across flavors | F41: =AVERAGE($F$35:$F$40)
A42: UNPRICED in the source data: Lemon Extract 4g, Lemon Poppy Seed 6g (Lemon Poppy); Ube Powder 20g (Ube). Add them here if you have prices:
A43: Extra flavoring cost per unit, not yet priced | B43: 0
A45: D · TIME COST — labor + commercial kitchen (minutes are real; the two rates are yours)
A46: =" Formula: minutes = "&Inputs!$B$25&" setup + batches x ("&Inputs!$B$26&" prep + "&Inputs!$B$27&" bake). Batch yield "&Inputs!$B$24&"."
A47: Units baked in a session | B47: Batches | C47: Minutes | D47: Hours | E47: Labor+kitchen $/unit | F47: Min/unit
...

Sheet Sensitivity
A1: SENSITIVITY — annual profit at 5 items
A2: Rows = units/day per item. Columns = wholesale % of MSRP. Uses the bake frequency, setup treatment and cost basis set on Inputs.
A3: =" At "&TEXT(Inputs!$B$32,"0")&" bake sessions/week, setup "&Inputs!$B$31&", materials $"&TEXT(Inputs!$B$20,"0.00")&"/unit, time $"&TEXT(Inputs!$B$30,"0")&"/hr"
B4: 0.4 | C4: 0.45 | D4: 0.5 | E4: 0.55 | F4: 0.6
A5: Units/day per item | B5: 40% | C5: 45% | D5: 50% | E5: 55% | F5: 60%
A6: 5 | B6: =(Inputs!$B$22*$A6*7*SUM(Items!$C$5:$C$9)*B$4-Inputs!$B$22*$A6*7*5*Inputs!$B$20-IF(Inputs!$B$21="Yes",IF(Inputs!$B$31="Shared",Inputs!$B$32*(Inputs!$B$25+5*ROUNDUP(Inputs!$B$22*$A6*7/Inputs!$B$32/Inputs!$B$24,0)*(Inputs!$B$26+Inputs!$B$27))/60,Inputs!$B$32*5*(Inputs!$B$25+ROUNDUP(Inputs!$B$22*$A6*7/Inputs!$B$32/Inputs!$B$24,0)*(Inputs!$B$26+Inputs!$B$27))/60)*Inputs!$B$30,0))*52 | C6: =(Inputs!$B$22*$A6*7*SUM(Items!$C$5:$C$9)*C$4-Inputs!$B$22*$A6*7*5*Inputs!$B$20-IF(Inputs!$B$21="Yes",IF(Inputs!$B$31="Shared",Inputs!$B$32*(Inputs!$B$25+5*ROUNDUP(Inputs!$B$22*$A6*7/Inputs!$B$32/Inputs!$B$24,0)*(Inputs!$B$26+Inputs!$B$27))/60,Inputs!$B$32*5*(Inputs!$B$25+ROUNDUP(Inputs!$B$22*$A6*7/Inputs!$B$32/Inputs!$B$24,0)*(Inputs!$B$26+Inputs!$B$27))/60)*Inputs!$B$30,0))*52 | D6: =(Inputs!$B$22*$A6*7*SUM(Items!$C$5:$C$9)*D$4-Inputs!$B$22*$A6*7*5*Inputs!$B$20-IF(Inputs!$B$21="Yes",IF(Inputs!$B$31="Shared",Inputs!$B$32*(Inputs!$B$25+5*ROUNDUP(Inputs!$B$22*$A6*7/Inputs!$B$32/Inputs!$B$24,0)*(Inputs!$B$26+Inputs!$B$27))/60,Inputs!$B$32*5*(Inputs!$B$25+ROUNDUP(Inputs!$B$22*$A6*7/Inputs!$B$32/Inputs!$B$24,0)*(Inputs!$B$26+Inputs!$B$27))/60)*Inputs!$B$30,0))*52 | E6: =(Inputs!$B$22*$A6*7*SUM(Items!$C$5:$C$9)*E$4-Inputs!$B$22*$A6*7*5*Inputs!$B$20-IF(Inputs!$B$21="Yes",IF(Inputs!$B$31="Shared",Inputs!$B$32*(Inputs!$B$25+5*ROUNDUP(Inputs!$B$22*$A6*7/Inputs!$B$32/Inputs!$B$24,0)*(Inputs!$B$26+Inputs!$B$27))/60,Inputs!$B$32*5*(Inputs!$B$25+ROUNDUP(Inputs!$B$22*$A6*7/Inputs!$B$32/Inputs!$B$24,0)*(Inputs!$B$26+Inputs!$B$27))/60)*Inputs!$B$30,0))*52 | F6: =(Inputs!$B$22*$A6*7*SUM(Items!$C$5:$C$9)*F$4-Inputs!$B$22*$A6*7*5*Inputs!$B$20-IF(Inputs!$B$21="Yes",IF(Inputs!$B$31="Shared",Inputs!$B$32*(Inputs!$B$25+5*ROUNDUP(Inputs!$B$22*$A6*7/Inputs!$B$32/Inputs!$B$24,0)*(Inputs!$B$26+Inputs!$B$27))/60,Inputs!$B$32*5*(Inputs!$B$25+ROUNDUP(Inputs!$B$22*$A6*7/Inputs!$B$32/Inputs!$B$24,0)*(Inputs!$B$26+Inputs!$B$27))/60)*Inputs!$B$30,0))*52
A7: 7 | B7: =(Inputs!$B$22*$A7*7*SUM(Items!$C$5:$C$9)*B$4-Inputs!$B$22*$A7*7*5*Inputs!$B$20-IF(Inputs!$B$21="Yes",IF(Inputs!$B$31="Shared",Inputs!$B$32*(Inputs!$B$25+5*ROUNDUP(Inputs!$B$22*$A7*7/Inputs!$B$32/Inputs!$B$24,0)*(Inputs!$B$26+Inputs!$B$27))/60,Inputs!$B$32*5*(Inputs!$B$25+ROUNDUP(Inputs!$B$22*$A7*7/Inputs!$B$32/Inputs!$B$24,0)*(Inputs!$B$26+Inputs!$B$27))/60)*Inputs!$B$30,0))*52 | C7: =(Inputs!$B$22*$A7*7*SUM(Items!$C$5:$C$9)*C$4-Inputs!$B$22*$A7*7*5*Inputs!$B$20-IF(Inputs!$B$21="Yes",IF(Inputs!$B$31="Shared",Inputs!$B$32*(Inputs!$B$25+5*ROUNDUP(Inputs!$B$22*$A7*7/Inputs!$B$32/Inputs!$B$24,0)*(Inputs!$B$26+Inputs!$B$27))/60,Inputs!$B$32*5*(Inputs!$B$25+ROUNDUP(Inputs!$B$22*$A7*7/Inputs!$B$32/Inputs!$B$24,0)*(Inputs!$B$26+Inputs!$B$27))/60)*Inputs!$B$30,0))*52 | D7: =(Inputs!$B$22*$A7*7*SUM(Items!$C$5:$C$9)*D$4-Inputs!$B$22*$A7*7*5*Inputs!$B$20-IF(Inputs!$B$21="Yes",IF(Inputs!$B$31="Shared",Inputs!$B$32*(Inputs!$B$25+5*ROUNDUP(Inputs!$B$22*$A7*7/Inputs!$B$32/Inputs!$B$24,0)*(Inputs!$B$26+Inputs!$B$27))/60,Inputs!$B$32*5*(Inputs!$B$25+ROUNDUP(Inputs!$B$22*$A7*7/Inputs!$B$32/Inputs!$B$24,0)*(Inputs!$B$26+Inputs!$B$27))/60)*Inputs!$B$30,0))*52 | E7: =(Inputs!$B$22*$A7*7*SUM(Items!$C$5:$C$9)*E$4-Inputs!$B$22*$A7*7*5*Inputs!$B$20-IF(Inputs!$B$21="Yes",IF(Inputs!$B$31="Shared",Inputs!$B$32*(Inputs!$B$25+5*ROUNDUP(Inputs!$B$22*$A7*7/Inputs!$B$32/Inputs!$B$24,0)*(Inputs!$B$26+Inputs!$B$27))/60,Inputs!$B$32*5*(Inputs!$B$25+ROUNDUP(Inputs!$B$22*$A7*7/Inputs!$B$32/Inputs!$B$24,0)*(Inputs!$B$26+Inputs!$B$27))/60)*Inputs!$B$30,0))*52 | F7: =(Inputs!$B$22*$A7*7*SUM(Items!$C$5:$C$9)*F$4-Inputs!$B$22*$A7*7*5*Inputs!$B$20-IF(Inputs!$B$21="Yes",IF(Inputs!$B$31="Shared",Inputs!$B$32*(Inputs!$B$25+5*ROUNDUP(Inputs!$B$22*$A7*7/Inputs!$B$32/Inputs!$B$24,0)*(Inputs!$B$26+Inputs!$B$27))/60,Inputs!$B$32*5*(Inputs!$B$25+ROUNDUP(Inputs!$B$22*$A7*7/Inputs!$B$32/Inputs!$B$24,0)*(Inputs!$B$26+Inputs!$B$27))/60)*Inputs!$B$30,0))*52
A8: 10 | B8: =(Inputs!$B$22*$A8*7*SUM(Items!$C$5:$C$9)*B$4-Inputs!$B$22*$A8*7*5*Inputs!$B$20-IF(Inputs!$B$21="Yes",IF(Inputs!$B$31="Shared",Inputs!$B$32*(Inputs!$B$25+5*ROUNDUP(Inputs!$B$22*$A8*7/Inputs!$B$32/Inputs!$B$24,0)*(Inputs!$B$26+Inputs!$B$27))/60,Inputs!$B$32*5*(Inputs!$B$25+ROUNDUP(Inputs!$B$22*$A8*7/Inputs!$B$32/Inputs!$B$24,0)*(Inputs!$B$26+Inputs!$B$27))/60)*Inputs!$B$30,0))*52 | C8: =(Inputs!$B$22*$A8*7*SUM(Items!$C$5:$C$9)*C$4-Inputs!$B$22*$A8*7*5*Inputs!$B$20-IF(Inputs!$B$21="Yes",IF(Inputs!$B$31="Shared",Inputs!$B$32*(Inputs!$B$25+5*ROUNDUP(Inputs!$B$22*$A8*7/Inputs!$B$32/Inputs!$B$24,0)*(Inputs!$B$26+Inputs!$B$27))/60,Inputs!$B$32*5*(Inputs!$B$25+ROUNDUP(Inputs!$B$22*$A8*7/Inputs!$B$32/Inputs!$B$24,0)*(Inputs!$B$26+Inputs!$B$27))/60)*Inputs!$B$30,0))*52 | D8: =(Inputs!$B$22*$A8*7*SUM(Items!$C$5:$C$9)*D$4-Inputs!$B$22*$A8*7*5*Inputs!$B$20-IF(Inputs!$B$21="Yes",IF(Inputs!$B$31="Shared",Inputs!$B$32*(Inputs!$B$25+5*ROUNDUP(Inputs!$B$22*$A8*7/Inputs!$B$32/Inputs!$B$24,0)*(Inputs!$B$26+Inputs!$B$27))/60,Inputs!$B$32*5*(Inputs!$B$25+ROUNDUP(Inputs!$B$22*$A8*7/Inputs!$B$32/Inputs!$B$24,0)*(Inputs!$B$26+Inputs!$B$27))/60)*Inputs!$B$30,0))*52 | E8: =(Inputs!$B$22*$A8*7*SUM(Items!$C$5:$C$9)*E$4-Inputs!$B$22*$A8*7*5*Inputs!$B$20-IF(Inputs!$B$21="Yes",IF(Inputs!$B$31="Shared",Inputs!$B$32*(Inputs!$B$25+5*ROUNDUP(Inputs!$B$22*$A8*7/Inputs!$B$32/Inputs!$B$24,0)*(Inputs!$B$26+Inputs!$B$27))/60,Inputs!$B$32*5*(Inputs!$B$25+ROUNDUP(Inputs!$B$22*$A8*7/Inputs!$B$32/Inputs!$B$24,0)*(Inputs!$B$26+Inputs!$B$27))/60)*Inputs!$B$30,0))*52 | F8: =(Inputs!$B$22*$A8*7*SUM(Items!$C$5:$C$9)*F$4-Inputs!$B$22*$A8*7*5*Inputs!$B$20-IF(Inputs!$B$21="Yes",IF(Inputs!$B$31="Shared",Inputs!$B$32*(Inputs!$B$25+5*ROUNDUP(Inputs!$B$22*$A8*7/Inputs!$B$32/Inputs!$B$24,0)*(Inputs!$B$26+Inputs!$B$27))/60,Inputs!$B$32*5*(Inputs!$B$25+ROUNDUP(Inputs!$B$22*$A8*7/Inputs!$B$32/Inputs!$B$24,0)*(Inputs!$B$26+Inputs!$B$27))/60)*Inputs!$B$30,0))*52
A9: 15 | B9: =(Inputs!$B$22*$A9*7*SUM(Items!$C$5:$C$9)*B$4-Inputs!$B$22*$A9*7*5*Inputs!$B$20-IF(Inputs!$B$21="Yes",IF(Inputs!$B$31="Shared",Inputs!$B$32*(Inputs!$B$25+5*ROUNDUP(Inputs!$B$22*$A9*7/Inputs!$B$32/Inputs!$B$24,0)*(Inputs!$B$26+Inputs!$B$27))/60,Inputs!$B$32*5*(Inputs!$B$25+ROUNDUP(Inputs!$B$22*$A9*7/Inputs!$B$32/Inputs!$B$24,0)*(Inputs!$B$26+Inputs!$B$27))/60)*Inputs!$B$30,0))*52 | C9: =(Inputs!$B$22*$A9*7*SUM(Items!$C$5:$C$9)*C$4-Inputs!$B$22*$A9*7*5*Inputs!$B$20-IF(Inputs!$B$21="Yes",IF(Inputs!$B$31="Shared",Inputs!$B$32*(Inputs!$B$25+5*ROUNDUP(Inputs!$B$22*$A9*7/Inputs!$B$32/Inputs!$B$24,0)*(Inputs!$B$26+Inputs!$B$27))/60,Inputs!$B$32*5*(Inputs!$B$25+ROUNDUP(Inputs!$B$22*$A9*7/Inputs!$B$32/Inputs!$B$24,0)*(Inputs!$B$26+Inputs!$B$27))/60)*Inputs!$B$30,0))*52 | D9: =(Inputs!$B$22*$A9*7*SUM(Items!$C$5:$C$9)*D$4-Inputs!$B$22*$A9*7*5*Inputs!$B$20-IF(Inputs!$B$21="Yes",IF(Inputs!$B$31="Shared",Inputs!$B$32*(Inputs!$B$25+5*ROUNDUP(Inputs!$B$22*$A9*7/Inputs!$B$32/Inputs!$B$24,0)*(Inputs!$B$26+Inputs!$B$27))/60,Inputs!$B$32*5*(Inputs!$B$25+ROUNDUP(Inputs!$B$22*$A9*7/Inputs!$B$32/Inputs!$B$24,0)*(Inputs!$B$26+Inputs!$B$27))/60)*Inputs!$B$30,0))*52 | E9: =(Inputs!$B$22*$A9*7*SUM(Items!$C$5:$C$9)*E$4-Inputs!$B$22*$A9*7*5*Inputs!$B$20-IF(Inputs!$B$21="Yes",IF(Inputs!$B$31="Shared",Inputs!$B$32*(Inputs!$B$25+5*ROUNDUP(Inputs!$B$22*$A9*7/Inputs!$B$32/Inputs!$B$24,0)*(Inputs!$B$26+Inputs!$B$27))/60,Inputs!$B$32*5*(Inputs!$B$25+ROUNDUP(Inputs!$B$22*$A9*7/Inputs!$B$32/Inputs!$B$24,0)*(Inputs!$B$26+Inputs!$B$27))/60)*Inputs!$B$30,0))*52 | F9: =(Inputs!$B$22*$A9*7*SUM(Items!$C$5:$C$9)*F$4-Inputs!$B$22*$A9*7*5*Inputs!$B$20-IF(Inputs!$B$21="Yes",IF(Inputs!$B$31="Shared",Inputs!$B$32*(Inputs!$B$25+5*ROUNDUP(Inputs!$B$22*$A9*7/Inputs!$B$32/Inputs!$B$24,0)*(Inputs!$B$26+Inputs!$B$27))/60,Inputs!$B$32*5*(Inputs!$B$25+ROUNDUP(Inputs!$B$22*$A9*7/Inputs!$B$32/Inputs!$B$24,0)*(Inputs!$B$26+Inputs!$B$27))/60)*Inputs!$B$30,0))*52
A10: 20 | B10: =(Inputs!$B$22*$A10*7*SUM(Items!$C$5:$C$9)*B$4-Inputs!$B$22*$A10*7*5*Inputs!$B$20-IF(Inputs!$B$21="Yes",IF(Inputs!$B$31="Shared",Inputs!$B$32*(Inputs!$B$25+5*ROUNDUP(Inputs!$B$22*$A10*7/Inputs!$B$32/Inputs!$B$24,0)*(Inputs!$B$26+Inputs!$B$27))/60,Inputs!$B$32*5*(Inputs!$B$25+ROUNDUP(Inputs!$B$22*$A10*7/Inputs!$B$32/Inputs!$B$24,0)*(Inputs!$B$26+Inputs!$B$27))/60)*Inputs!$B$30,0))*52 | C10: =(Inputs!$B$22*$A10*7*SUM(Items!$C$5:$C$9)*C$4-Inputs!$B$22*$A10*7*5*Inputs!$B$20-IF(Inputs!$B$21="Yes",IF(Inputs!$B$31="Shared",Inputs!$B$32*(Inputs!$B$25+5*ROUNDUP(Inputs!$B$22*$A10*7/Inputs!$B$32/Inputs!$B$24,0)*(Inputs!$B$26+Inputs!$B$27))/60,Inputs!$B$32*5*(Inputs!$B$25+ROUNDUP(Inputs!$B$22*$A10*7/Inputs!$B$32/Inputs!$B$24,0)*(Inputs!$B$26+Inputs!$B$27))/60)*Inputs!$B$30,0))*52 | D10: =(Inputs!$B$22*$A10*7*SUM(Items!$C$5:$C$9)*D$4-Inputs!$B$22*$A10*7*5*Inputs!$B$20-IF(Inputs!$B$21="Yes",IF(Inputs!$B$31="Shared",Inputs!$B$32*(Inputs!$B$25+5*ROUNDUP(Inputs!$B$22*$A10*7/Inputs!$B$32/Inputs!$B$24,0)*(Inputs!$B$26+Inputs!$B$27))/60,Inputs!$B$32*5*(Inputs!$B$25+ROUNDUP(Inputs!$B$22*$A10*7/Inputs!$B$32/Inputs!$B$24,0)*(Inputs!$B$26+Inputs!$B$27))/60)*Inputs!$B$30,0))*52 | E10: =(Inputs!$B$22*$A10*7*SUM(Items!$C$5:$C$9)*E$4-Inputs!$B$22*$A10*7*5*Inputs!$B$20-IF(Inputs!$B$21="Yes",IF(Inputs!$B$31="Shared",Inputs!$B$32*(Inputs!$B$25+5*ROUNDUP(Inputs!$B$22*$A10*7/Inputs!$B$32/Inputs!$B$24,0)*(Inputs!$B$26+Inputs!$B$27))/60,Inputs!$B$32*5*(Inputs!$B$25+ROUNDUP(Inputs!$B$22*$A10*7/Inputs!$B$32/Inputs!$B$24,0)*(Inputs!$B$26+Inputs!$B$27))/60)*Inputs!$B$30,0))*52 | F10: =(Inputs!$B$22*$A10*7*SUM(Items!$C$5:$C$9)*F$4-Inputs!$B$22*$A10*7*5*Inputs!$B$20-IF(Inputs!$B$21="Yes",IF(Inputs!$B$31="Shared",Inputs!$B$32*(Inputs!$B$25+5*ROUNDUP(Inputs!$B$22*$A10*7/Inputs!$B$32/Inputs!$B$24,0)*(Inputs!$B$26+Inputs!$B$27))/60,Inputs!$B$32*5*(Inputs!$B$25+ROUNDUP(Inputs!$B$22*$A10*7/Inputs!$B$32/Inputs!$B$24,0)*(Inputs!$B$26+Inputs!$B$27))/60)*Inputs!$B$30,0))*52
A11: 30 | B11: =(Inputs!$B$22*$A11*7*SUM(Items!$C$5:$C$9)*B$4-Inputs!$B$22*$A11*7*5*Inputs!$B$20-IF(Inputs!$B$21="Yes",IF(Inputs!$B$31="Shared",Inputs!$B$32*(Inputs!$B$25+5*ROUNDUP(Inputs!$B$22*$A11*7/Inputs!$B$32/Inputs!$B$24,0)*(Inputs!$B$26+Inputs!$B$27))/60,Inputs!$B$32*5*(Inputs!$B$25+ROUNDUP(Inputs!$B$22*$A11*7/Inputs!$B$32/Inputs!$B$24,0)*(Inputs!$B$26+Inputs!$B$27))/60)*Inputs!$B$30,0))*52 | C11: =(Inputs!$B$22*$A11*7*SUM(Items!$C$5:$C$9)*C$4-Inputs!$B$22*$A11*7*5*Inputs!$B$20-IF(Inputs!$B$21="Yes",IF(Inputs!$B$31="Shared",Inputs!$B$32*(Inputs!$B$25+5*ROUNDUP(Inputs!$B$22*$A11*7/Inputs!$B$32/Inputs!$B$24,0)*(Inputs!$B$26+Inputs!$B$27))/60,Inputs!$B$32*5*(Inputs!$B$25+ROUNDUP(Inputs!$B$22*$A11*7/Inputs!$B$32/Inputs!$B$24,0)*(Inputs!$B$26+Inputs!$B$27))/60)*Inputs!$B$30,0))*52 | D11: =(Inputs!$B$22*$A11*7*SUM(Items!$C$5:$C$9)*D$4-Inputs!$B$22*$A11*7*5*Inputs!$B$20-IF(Inputs!$B$21="Yes",IF(Inputs!$B$31="Shared",Inputs!$B$32*(Inputs!$B$25+5*ROUNDUP(Inputs!$B$22*$A11*7/Inputs!$B$32/Inputs!$B$24,0)*(Inputs!$B$26+Inputs!$B$27))/60,Inputs!$B$32*5*(Inputs!$B$25+ROUNDUP(Inputs!$B$22*$A11*7/Inputs!$B$32/Inputs!$B$24,0)*(Inputs!$B$26+Inputs!$B$27))/60)*Inputs!$B$30,0))*52 | E11: =(Inputs!$B$22*$A11*7*SUM(Items!$C$5:$C$9)*E$4-Inputs!$B$22*$A11*7*5*Inputs!$B$20-IF(Inputs!$B$21="Yes",IF(Inputs!$B$31="Shared",Inputs!$B$32*(Inputs!$B$25+5*ROUNDUP(Inputs!$B$22*$A11*7/Inputs!$B$32/Inputs!$B$24,0)*(Inputs!$B$26+Inputs!$B$27))/60,Inputs!$B$32*5*(Inputs!$B$25+ROUNDUP(Inputs!$B$22*$A11*7/Inputs!$B$32/Inputs!$B$24,0)*(Inputs!$B$26+Inputs!$B$27))/60)*Inputs!$B$30,0))*52 | F11: =(Inputs!$B$22*$A11*7*SUM(Items!$C$5:$C$9)*F$4-Inputs!$B$22*$A11*7*5*Inputs!$B$20-IF(Inputs!$B$21="Yes",IF(Inputs!$B$31="Shared",Inputs!$B$32*(Inputs!$B$25+5*ROUNDUP(Inputs!$B$22*$A11*7/Inputs!$B$32/Inputs!$B$24,0)*(Inputs!$B$26+Inputs!$B$27))/60,Inputs!$B$32*5*(Inputs!$B$25+ROUNDUP(Inputs!$B$22*$A11*7/Inputs!$B$32/Inputs!$B$24,0)*(Inputs!$B$26+Inputs!$B$27))/60)*Inputs!$B$30,0))*52
A12: 50 | B12: =(Inputs!$B$22*$A12*7*SUM(Items!$C$5:$C$9)*B$4-Inputs!$B$22*$A12*7*5*Inputs!$B$20-IF(Inputs!$B$21="Yes",IF(Inputs!$B$31="Shared",Inputs!$B$32*(Inputs!$B$25+5*ROUNDUP(Inputs!$B$22*$A12*7/Inputs!$B$32/Inputs!$B$24,0)*(Inputs!$B$26+Inputs!$B$27))/60,Inputs!$B$32*5*(Inputs!$B$25+ROUNDUP(Inputs!$B$22*$A12*7/Inputs!$B$32/Inputs!$B$24,0)*(Inputs!$B$26+Inputs!$B$27))/60)*Inputs!$B$30,0))*52 | C12: =(Inputs!$B$22*$A12*7*SUM(Items!$C$5:$C$9)*C$4-Inputs!$B$22*$A12*7*5*Inputs!$B$20-IF(Inputs!$B$21="Yes",IF(Inputs!$B$31="Shared",Inputs!$B$32*(Inputs!$B$25+5*ROUNDUP(Inputs!$B$22*$A12*7/Inputs!$B$32/Inputs!$B$24,0)*(Inputs!$B$26+Inputs!$B$27))/60,Inputs!$B$32*5*(Inputs!$B$25+ROUNDUP(Inputs!$B$22*$A12*7/Inputs!$B$32/Inputs!$B$24,0)*(Inputs!$B$26+Inputs!$B$27))/60)*Inputs!$B$30,0))*52 | D12: =(Inputs!$B$22*$A12*7*SUM(Items!$C$5:$C$9)*D$4-Inputs!$B$22*$A12*7*5*Inputs!$B$20-IF(Inputs!$B$21="Yes",IF(Inputs!$B$31="Shared",Inputs!$B$32*(Inputs!$B$25+5*ROUNDUP(Inputs!$B$22*$A12*7/Inputs!$B$32/Inputs!$B$24,0)*(Inputs!$B$26+Inputs!$B$27))/60,Inputs!$B$32*5*(Inputs!$B$25+ROUNDUP(Inputs!$B$22*$A12*7/Inputs!$B$32/Inputs!$B$24,0)*(Inputs!$B$26+Inputs!$B$27))/60)*Inputs!$B$30,0))*52 | E12: =(Inputs!$B$22*$A12*7*SUM(Items!$C$5:$C$9)*E$4-Inputs!$B$22*$A12*7*5*Inputs!$B$20-IF(Inputs!$B$21="Yes",IF(Inputs!$B$31="Shared",Inputs!$B$32*(Inputs!$B$25+5*ROUNDUP(Inputs!$B$22*$A12*7/Inputs!$B$32/Inputs!$B$24,0)*(Inputs!$B$26+Inputs!$B$27))/60,Inputs!$B$32*5*(Inputs!$B$25+ROUNDUP(Inputs!$B$22*$A12*7/Inputs!$B$32/Inputs!$B$24,0)*(Inputs!$B$26+Inputs!$B$27))/60)*Inputs!$B$30,0))*52 | F12: =(Inputs!$B$22*$A12*7*SUM(Items!$C$5:$C$9)*F$4-Inputs!$B$22*$A12*7*5*Inputs!$B$20-IF(Inputs!$B$21="Yes",IF(Inputs!$B$31="Shared",Inputs!$B$32*(Inputs!$B$25+5*ROUNDUP(Inputs!$B$22*$A12*7/Inputs!$B$32/Inputs!$B$24,0)*(Inputs!$B$26+Inputs!$B$27))/60,Inputs!$B$32*5*(Inputs!$B$25+ROUNDUP(Inputs!$B$22*$A12*7/Inputs!$B$32/Inputs!$B$24,0)*(Inputs!$B$26+Inputs!$B$27))/60)*Inputs!$B$30,0))*52
A14: Any cell at or below zero means five SKUs at that volume and that wholesale rate do not cover cost.
A15: If the grid is all red, the fix is not price — it is Inputs!B32 (bake less often, bake bigger) or Inputs!B24 (bigger batches).

Sheet BreakEven
A1: BREAK-EVEN — can wholesale work at all?
A2: Time cost per unit has a floor: even with infinitely many units, you still pay prep+bake for every 20-unit batch. If that floor exceeds your margin, no volume rescues it.
A4: A · THE FLOOR (what a unit costs when volume is unlimited and setup rounds to nothing)
A5: Blended MSRP across the 5 items | B5: =AVERAGE(Items!$C$5:$C$9) | G5: Items tab
A6: Blended wholesale price | B6: =$B$5*Inputs!$B$14 | G6: at Inputs!B14
A7: Materials per unit (basis in use) | B7: =Inputs!$B$20 | G7: Flat or Computed, per Inputs!B18
A8: Margin available for time, per unit | B8: =$B$6-$B$7 | G8: everything left to pay labor+kitchen
A9: Minutes per unit at a FULL batch | B9: =(Inputs!$B$26+Inputs!$B$27)/Inputs!$B$24 | G9: (prep+bake)/yield — setup excluded, this is the floor
A10: Floor time cost per unit | B10: =$B$9/60*Inputs!$B$30 | G10: at the combined hourly rate
A11: Contribution per unit at the floor | B11: =$B$8-$B$10 | G11: POSITIVE = viable at high volume
A12: =IF($B$11>0,"VIABLE at high volume — the question is only how fast you get there.","NOT VIABLE AT ANY VOLUME with these settings. Fix one of: batch yield, hourly rate, materials cost, or wholesale %.")
A14: B · WHAT WOULD HAVE TO CHANGE
A15: Batch yield needed to break even | B15: =IFERROR((Inputs!$B$26+Inputs!$B$27)/60*Inputs!$B$30/$B$8,0) | G15: units per batch, at the current rate and margin
A16: Combined $/hr the current yield can carry | B16: =IFERROR($B$8/($B$9/60),0) | G16: vs your $80/hr — the gap is the problem
A17: Wholesale % needed at the floor | B17: =IFERROR(($B$7+$B$10)/$B$5,0) | G17: share of MSRP that just covers materials + floor time
A18: Materials budget at 50% wholesale | B18: =$B$6-$B$10 | G18: what a unit's ingredients must cost to break even at the floor
A20: C · COST PER UNIT BY SESSION SIZE (one SKU, one bake session)
A21: Units per session | B21: Batches | C21: Minutes | D21: Time $/unit | E21: All-in $/unit | F21: Contribution $/unit | G21: Profit per session
A22: 10 | B22: =ROUNDUP($A22/Inputs!$B$24,0) | C22: =Inputs!$B$25+$B22*(Inputs!$B$26+Inputs!$B$27) | D22: =IFERROR($C22/60*Inputs!$B$30/$A22,0) | E22: =$D22+Inputs!$B$20 | F22: =$B$6-$E22 | G22: =$F22*$A22
A23: 20 | B23: =ROUNDUP($A23/Inputs!$B$24,0) | C23: =Inputs!$B$25+$B23*(Inputs!$B$26+Inputs!$B$27) | D23: =IFERROR($C23/60*Inputs!$B$30/$A23,0) | E23: =$D23+Inputs!$B$20 | F23: =$B$6-$E23 | G23: =$F23*$A23
A24: 40 | B24: =ROUNDUP($A24/Inputs!$B$24,0) | C24: =Inputs!$B$25+$B24*(Inputs!$B$26+Inputs!$B$27) | D24: =IFERROR($C24/60*Inputs!$B$30/$A24,0) | E24: =$D24+Inputs!$B$20 | F24: =$B$6-$E24 | G24: =$F24*$A24
A25: 60 | B25: =ROUNDUP($A25/Inputs!$B$24,0) | C25: =Inputs!$B$25+$B25*(Inputs!$B$26+Inputs!$B$27) | D25: =IFERROR($C25/60*Inputs!$B$30/$A25,0) | E25: =$D25+Inputs!$B$20 | F25: =$B$6-$E25 | G25: =$F25*$A25
A26: 100 | B26: =ROUNDUP($A26/Inputs!$B$24,0) | C26: =Inputs!$B$25+$B26*(Inputs!$B$26+Inputs!$B$27) | D26: =IFERROR($C26/60*Inputs!$B$30/$A26,0) | E26: =$D26+Inputs!$B$20 | F26: =$B$6-$E26 | G26: =$F26*$A26
A27: 140 | B27: =ROUNDUP($A27/Inputs!$B$24,0) | C27: =Inputs!$B$25+$B27*(Inputs!$B$26+Inputs!$B$27) | D27: =IFERROR($C27/60*Inputs!$B$30/$A27,0) | E27: =$D27+Inputs!$B$20 | F27: =$B$6-$E27 | G27: =$F27*$A27
A28: 200 | B28: =ROUNDUP($A28/Inputs!$B$24,0) | C28: =Inputs!$B$25+$B28*(Inputs!$B$26+Inputs!$B$27) | D28: =IFERROR($C28/60*Inputs!$B$30/$A28,0) | E28: =$D28+Inputs!$B$20 | F28: =$B$6-$E28 | G28: =$F28*$A28
A29: 300 | B29: =ROUNDUP($A29/Inputs!$B$24,0) | C29: =Inputs!$B$25+$B29*(Inputs!$B$26+Inputs!$B$27) | D29: =IFERROR($C29/60*Inputs!$B$30/$A29,0) | E29: =$D29+Inputs!$B$20 | F29: =$B$6-$E29 | G29: =$F29*$A29
A30: 400 | B30: =ROUNDUP($A30/Inputs!$B$24,0) | C30: =Inputs!$B$25+$B30*(Inputs!$B$26+Inputs!$B$27) | D30: =IFERROR($C30/60*Inputs!$B$30/$A30,0) | E30: =$D30+Inputs!$B$20 | F30: =$B$6-$E30 | G30: =$F30*$A30
A32: Column F turns positive at the volume where wholesale finally covers cost. If it never does, section A already told you why.
A34: D · THE SAME TABLE IF YOU RAISE BATCH YIELD
A35: Bigger trays or a bigger oven is the single highest-leverage change: it divides the 29 min of prep+bake across more units.
A36: Batch yield | B36: Min/unit at floor | C36: Floor time $/unit | D36: Contribution at floor
A37: 20 | B37: =(Inputs!$B$26+Inputs!$B$27)/$A37 | C37: =$B37/60*Inputs!$B$30 | D37: =$B$8-$C37
A38: 30 | B38: =(Inputs!$B$26+Inputs!$B$27)/$A38 | C38: =$B38/60*Inputs!$B$30 | D38: =$B$8-$C38
A39: 40 | B39: =(Inputs!$B$26+Inputs!$B$27)/$A39 | C39: =$B39/60*Inputs!$B$30 | D39: =$B$8-$C39
A40: 60 | B40: =(Inputs!$B$26+Inputs!$B$27)/$A40 | C40: =$B40/60*Inputs!$B$30 | D40: =$B$8-$C40
A41: 80 | B41: =(Inputs!$B$26+Inputs!$B$27)/$A41 | C41: =$B41/60*Inputs!$B$30 | D41: =$B$8-$C41
A42: 100 | B42: =(Inputs!$B$26+Inputs!$B$27)/$A42 | C42: =$B42/60*Inputs!$B$30 | D42: =$B$8-$C42

Sheet Path
A1: THE PATH FROM 1 SKU TO 5
A2: You have one product in one account today. This grid separates the two ways to grow: more SKUs on one shelf (down) versus the same SKUs in more accounts (across).
A3: =" Annual profit · "&TEXT(Inputs!$B$12,"0")&" units/day per item per account · "&TEXT(Inputs!$B$32,"0")&" bakes/week · setup "&Inputs!$B$31&" · batch yield "&TEXT(Inputs!$B$24,"0")&" · materials $"&TEXT(Inputs!$B$20,"0.00")&" · time $"&TEXT(Inputs!$B$30,"0")&"/hr"
A5: ANNUAL PROFIT rows = SKUs carried · columns = wholesale accounts | B5: 1 | C5: 2 | D5: 3 | E5: 5 | F5: 8 | G5: 12
A6: SKUs | B6: 1 account | C6: 2 accounts | D6: 3 accounts | E6: 5 accounts | F6: 8 accounts | G6: 12 accounts
A7: 1 SKU | B7: =(B$5*Inputs!$B$12*7*INDEX(Items!$I$5:$I$9,1)-B$5*Inputs!$B$12*7*INDEX(Items!$J$5:$J$9,1)-IF(Inputs!$B$21="Yes",IF(Inputs!$B$31="Shared",Inputs!$B$32*(Inputs!$B$25+1*ROUNDUP(B$5*Inputs!$B$12*7/Inputs!$B$32/Inputs!$B$24,0)*(Inputs!$B$26+Inputs!$B$27))/60,Inputs!$B$32*1*(Inputs!$B$25+ROUNDUP(B$5*Inputs!$B$12*7/Inputs!$B$32/Inputs!$B$24,0)*(Inputs!$B$26+Inputs!$B$27))/60)*Inputs!$B$30,0))*52 | C7: =(C$5*Inputs!$B$12*7*INDEX(Items!$I$5:$I$9,1)-C$5*Inputs!$B$12*7*INDEX(Items!$J$5:$J$9,1)-IF(Inputs!$B$21="Yes",IF(Inputs!$B$31="Shared",Inputs!$B$32*(Inputs!$B$25+1*ROUNDUP(C$5*Inputs!$B$12*7/Inputs!$B$32/Inputs!$B$24,0)*(Inputs!$B$26+Inputs!$B$27))/60,Inputs!$B$32*1*(Inputs!$B$25+ROUNDUP(C$5*Inputs!$B$12*7/Inputs!$B$32/Inputs!$B$24,0)*(Inputs!$B$26+Inputs!$B$27))/60)*Inputs!$B$30,0))*52 | D7: =(D$5*Inputs!$B$12*7*INDEX(Items!$I$5:$I$9,1)-D$5*Inputs!$B$12*7*INDEX(Items!$J$5:$J$9,1)-IF(Inputs!$B$21="Yes",IF(Inputs!$B$31="Shared",Inputs!$B$32*(Inputs!$B$25+1*ROUNDUP(D$5*Inputs!$B$12*7/Inputs!$B$32/Inputs!$B$24,0)*(Inputs!$B$26+Inputs!$B$27))/60,Inputs!$B$32*1*(Inputs!$B$25+ROUNDUP(D$5*Inputs!$B$12*7/Inputs!$B$32/Inputs!$B$24,0)*(Inputs!$B$26+Inputs!$B$27))/60)*Inputs!$B$30,0))*52 | E7: =(E$5*Inputs!$B$12*7*INDEX(Items!$I$5:$I$9,1)-E$5*Inputs!$B$12*7*INDEX(Items!$J$5:$J$9,1)-IF(Inputs!$B$21="Yes",IF(Inputs!$B$31="Shared",Inputs!$B$32*(Inputs!$B$25+1*ROUNDUP(E$5*Inputs!$B$12*7/Inputs!$B$32/Inputs!$B$24,0)*(Inputs!$B$26+Inputs!$B$27))/60,Inputs!$B$32*1*(Inputs!$B$25+ROUNDUP(E$5*Inputs!$B$12*7/Inputs!$B$32/Inputs!$B$24,0)*(Inputs!$B$26+Inputs!$B$27))/60)*Inputs!$B$30,0))*52 | F7: =(F$5*Inputs!$B$12*7*INDEX(Items!$I$5:$I$9,1)-F$5*Inputs!$B$12*7*INDEX(Items!$J$5:$J$9,1)-IF(Inputs!$B$21="Yes",IF(Inputs!$B$31="Shared",Inputs!$B$32*(Inputs!$B$25+1*ROUNDUP(F$5*Inputs!$B$12*7/Inputs!$B$32/Inputs!$B$24,0)*(Inputs!$B$26+Inputs!$B$27))/60,Inputs!$B$32*1*(Inputs!$B$25+ROUNDUP(F$5*Inputs!$B$12*7/Inputs!$B$32/Inputs!$B$24,0)*(Inputs!$B$26+Inputs!$B$27))/60)*Inputs!$B$30,0))*52 | G7: =(G$5*Inputs!$B$12*7*INDEX(Items!$I$5:$I$9,1)-G$5*Inputs!$B$12*7*INDEX(Items!$J$5:$J$9,1)-IF(Inputs!$B$21="Yes",IF(Inputs!$B$31="Shared",Inputs!$B$32*(Inputs!$B$25+1*ROUNDUP(G$5*Inputs!$B$12*7/Inputs!$B$32/Inputs!$B$24,0)*(Inputs!$B$26+Inputs!$B$27))/60,Inputs!$B$32*1*(Inputs!$B$25+ROUNDUP(G$5*Inputs!$B$12*7/Inputs!$B$32/Inputs!$B$24,0)*(Inputs!$B$26+Inputs!$B$27))/60)*Inputs!$B$30,0))*52 | H7: Read across, not down: accounts fill batches, SKUs fill sessions.
A8: 2 SKUs | B8: =(B$5*Inputs!$B$12*7*INDEX(Items!$I$5:$I$9,2)-B$5*Inputs!$B$12*7*INDEX(Items!$J$5:$J$9,2)-IF(Inputs!$B$21="Yes",IF(Inputs!$B$31="Shared",Inputs!$B$32*(Inputs!$B$25+2*ROUNDUP(B$5*Inputs!$B$12*7/Inputs!$B$32/Inputs!$B$24,0)*(Inputs!$B$26+Inputs!$B$27))/60,Inputs!$B$32*2*(Inputs!$B$25+ROUNDUP(B$5*Inputs!$B$12*7/Inputs!$B$32/Inputs!$B$24,0)*(Inputs!$B$26+Inputs!$B$27))/60)*Inputs!$B$30,0))*52 | C8: =(C$5*Inputs!$B$12*7*INDEX(Items!$I$5:$I$9,2)-C$5*Inputs!$B$12*7*INDEX(Items!$J$5:$J$9,2)-IF(Inputs!$B$21="Yes",IF(Inputs!$B$31="Shared",Inputs!$B$32*(Inputs!$B$25+2*ROUNDUP(C$5*Inputs!$B$12*7/Inputs!$B$32/Inputs!$B$24,0)*(Inputs!$B$26+Inputs!$B$27))/60,Inputs!$B$32*2*(Inputs!$B$25+ROUNDUP(C$5*Inputs!$B$12*7/Inputs!$B$32/Inputs!$B$24,0)*(Inputs!$B$26+Inputs!$B$27))/60)*Inputs!$B$30,0))*52 | D8: =(D$5*Inputs!$B$12*7*INDEX(Items!$I$5:$I$9,2)-D$5*Inputs!$B$12*7*INDEX(Items!$J$5:$J$9,2)-IF(Inputs!$B$21="Yes",IF(Inputs!$B$31="Shared",Inputs!$B$32*(Inputs!$B$25+2*ROUNDUP(D$5*Inputs!$B$12*7/Inputs!$B$32/Inputs!$B$24,0)*(Inputs!$B$26+Inputs!$B$27))/60,Inputs!$B$32*2*(Inputs!$B$25+ROUNDUP(D$5*Inputs!$B$12*7/Inputs!$B$32/Inputs!$B$24,0)*(Inputs!$B$26+Inputs!$B$27))/60)*Inputs!$B$30,0))*52 | E8: =(E$5*Inputs!$B$12*7*INDEX(Items!$I$5:$I$9,2)-E$5*Inputs!$B$12*7*INDEX(Items!$J$5:$J$9,2)-IF(Inputs!$B$21="Yes",IF(Inputs!$B$31="Shared",Inputs!$B$32*(Inputs!$B$25+2*ROUNDUP(E$5*Inputs!$B$12*7/Inputs!$B$32/Inputs!$B$24,0)*(Inputs!$B$26+Inputs!$B$27))/60,Inputs!$B$32*2*(Inputs!$B$25+ROUNDUP(E$5*Inputs!$B$12*7/Inputs!$B$32/Inputs!$B$24,0)*(Inputs!$B$26+Inputs!$B$27))/60)*Inputs!$B$30,0))*52 | F8: =(F$5*Inputs!$B$12*7*INDEX(Items!$I$5:$I$9,2)-F$5*Inputs!$B$12*7*INDEX(Items!$J$5:$J$9,2)-IF(Inputs!$B$21="Yes",IF(Inputs!$B$31="Shared",Inputs!$B$32*(Inputs!$B$25+2*ROUNDUP(F$5*Inputs!$B$12*7/Inputs!$B$32/Inputs!$B$24,0)*(Inputs!$B$26+Inputs!$B$27))/60,Inputs!$B$32*2*(Inputs!$B$25+ROUNDUP(F$5*Inputs!$B$12*7/Inputs!$B$32/Inputs!$B$24,0)*(Inputs!$B$26+Inputs!$B$27))/60)*Inputs!$B$30,0))*52 | G8: =(G$5*Inputs!$B$12*7*INDEX(Items!$I$5:$I$9,2)-G$5*Inputs!$B$12*7*INDEX(Items!$J$5:$J$9,2)-IF(Inputs!$B$21="Yes",IF(Inputs!$B$31="Shared",Inputs!$B$32*(Inputs!$B$25+2*ROUNDUP(G$5*Inputs!$B$12*7/Inputs!$B$32/Inputs!$B$24,0)*(Inputs!$B$26+Inputs!$B$27))/60,Inputs!$B$32*2*(Inputs!$B$25+ROUNDUP(G$5*Inputs!$B$12*7/Inputs!$B$32/Inputs!$B$24,0)*(Inputs!$B$26+Inputs!$B$27))/60)*Inputs!$B$30,0))*52
A9: 3 SKUs | B9: =(B$5*Inputs!$B$12*7*INDEX(Items!$I$5:$I$9,3)-B$5*Inputs!$B$12*7*INDEX(Items!$J$5:$J$9,3)-IF(Inputs!$B$21="Yes",IF(Inputs!$B$31="Shared",Inputs!$B$32*(Inputs!$B$25+3*ROUNDUP(B$5*Inputs!$B$12*7/Inputs!$B$32/Inputs!$B$24,0)*(Inputs!$B$26+Inputs!$B$27))/60,Inputs!$B$32*3*(Inputs!$B$25+ROUNDUP(B$5*Inputs!$B$12*7/Inputs!$B$32/Inputs!$B$24,0)*(Inputs!$B$26+Inputs!$B$27))/60)*Inputs!$B$30,0))*52 | C9: =(C$5*Inputs!$B$12*7*INDEX(Items!$I$5:$I$9,3)-C$5*Inputs!$B$12*7*INDEX(Items!$J$5:$J$9,3)-IF(Inputs!$B$21="Yes",IF(Inputs!$B$31="Shared",Inputs!$B$32*(Inputs!$B$25+3*ROUNDUP(C$5*Inputs!$B$12*7/Inputs!$B$32/Inputs!$B$24,0)*(Inputs!$B$26+Inputs!$B$27))/60,Inputs!$B$32*3*(Inputs!$B$25+ROUNDUP(C$5*Inputs!$B$12*7/Inputs!$B$32/Inputs!$B$24,0)*(Inputs!$B$26+Inputs!$B$27))/60)*Inputs!$B$30,0))*52 | D9: =(D$5*Inputs!$B$12*7*INDEX(Items!$I$5:$I$9,3)-D$5*Inputs!$B$12*7*INDEX(Items!$J$5:$J$9,3)-IF(Inputs!$B$21="Yes",IF(Inputs!$B$31="Shared",Inputs!$B$32*(Inputs!$B$25+3*ROUNDUP(D$5*Inputs!$B$12*7/Inputs!$B$32/Inputs!$B$24,0)*(Inputs!$B$26+Inputs!$B$27))/60,Inputs!$B$32*3*(Inputs!$B$25+ROUNDUP(D$5*Inputs!$B$12*7/Inputs!$B$32/Inputs!$B$24,0)*(Inputs!$B$26+Inputs!$B$27))/60)*Inputs!$B$30,0))*52 | E9: =(E$5*Inputs!$B$12*7*INDEX(Items!$I$5:$I$9,3)-E$5*Inputs!$B$12*7*INDEX(Items!$J$5:$J$9,3)-IF(Inputs!$B$21="Yes",IF(Inputs!$B$31="Shared",Inputs!$B$32*(Inputs!$B$25+3*ROUNDUP(E$5*Inputs!$B$12*7/Inputs!$B$32/Inputs!$B$24,0)*(Inputs!$B$26+Inputs!$B$27))/60,Inputs!$B$32*3*(Inputs!$B$25+ROUNDUP(E$5*Inputs!$B$12*7/Inputs!$B$32/Inputs!$B$24,0)*(Inputs!$B$26+Inputs!$B$27))/60)*Inputs!$B$30,0))*52 | F9: =(F$5*Inputs!$B$12*7*INDEX(Items!$I$5:$I$9,3)-F$5*Inputs!$B$12*7*INDEX(Items!$J$5:$J$9,3)-IF(Inputs!$B$21="Yes",IF(Inputs!$B$31="Shared",Inputs!$B$32*(Inputs!$B$25+3*ROUNDUP(F$5*Inputs!$B$12*7/Inputs!$B$32/Inputs!$B$24,0)*(Inputs!$B$26+Inputs!$B$27))/60,Inputs!$B$32*3*(Inputs!$B$25+ROUNDUP(F$5*Inputs!$B$12*7/Inputs!$B$32/Inputs!$B$24,0)*(Inputs!$B$26+Inputs!$B$27))/60)*Inputs!$B$30,0))*52 | G9: =(G$5*Inputs!$B$12*7*INDEX(Items!$I$5:$I$9,3)-G$5*Inputs!$B$12*7*INDEX(Items!$J$5:$J$9,3)-IF(Inputs!$B$21="Yes",IF(Inputs!$B$31="Shared",Inputs!$B$32*(Inputs!$B$25+3*ROUNDUP(G$5*Inputs!$B$12*7/Inputs!$B$32/Inputs!$B$24,0)*(Inputs!$B$26+Inputs!$B$27))/60,Inputs!$B$32*3*(Inputs!$B$25+ROUNDUP(G$5*Inputs!$B$12*7/Inputs!$B$32/Inputs!$B$24,0)*(Inputs!$B$26+Inputs!$B$27))/60)*Inputs!$B$30,0))*52
A10: 4 SKUs | B10: =(B$5*Inputs!$B$12*7*INDEX(Items!$I$5:$I$9,4)-B$5*Inputs!$B$12*7*INDEX(Items!$J$5:$J$9,4)-IF(Inputs!$B$21="Yes",IF(Inputs!$B$31="Shared",Inputs!$B$32*(Inputs!$B$25+4*ROUNDUP(B$5*Inputs!$B$12*7/Inputs!$B$32/Inputs!$B$24,0)*(Inputs!$B$26+Inputs!$B$27))/60,Inputs!$B$32*4*(Inputs!$B$25+ROUNDUP(B$5*Inputs!$B$12*7/Inputs!$B$32/Inputs!$B$24,0)*(Inputs!$B$26+Inputs!$B$27))/60)*Inputs!$B$30,0))*52 | C10: =(C$5*Inputs!$B$12*7*INDEX(Items!$I$5:$I$9,4)-C$5*Inputs!$B$12*7*INDEX(Items!$J$5:$J$9,4)-IF(Inputs!$B$21="Yes",IF(Inputs!$B$31="Shared",Inputs!$B$32*(Inputs!$B$25+4*ROUNDUP(C$5*Inputs!$B$12*7/Inputs!$B$32/Inputs!$B$24,0)*(Inputs!$B$26+Inputs!$B$27))/60,Inputs!$B$32*4*(Inputs!$B$25+ROUNDUP(C$5*Inputs!$B$12*7/Inputs!$B$32/Inputs!$B$24,0)*(Inputs!$B$26+Inputs!$B$27))/60)*Inputs!$B$30,0))*52 | D10: =(D$5*Inputs!$B$12*7*INDEX(Items!$I$5:$I$9,4)-D$5*Inputs!$B$12*7*INDEX(Items!$J$5:$J$9,4)-IF(Inputs!$B$21="Yes",IF(Inputs!$B$31="Shared",Inputs!$B$32*(Inputs!$B$25+4*ROUNDUP(D$5*Inputs!$B$12*7/Inputs!$B$32/Inputs!$B$24,0)*(Inputs!$B$26+Inputs!$B$27))/60,Inputs!$B$32*4*(Inputs!$B$25+ROUNDUP(D$5*Inputs!$B$12*7/Inputs!$B$32/Inputs!$B$24,0)*(Inputs!$B$26+Inputs!$B$27))/60)*Inputs!$B$30,0))*52 | E10: =(E$5*Inputs!$B$12*7*INDEX(Items!$I$5:$I$9,4)-E$5*Inputs!$B$12*7*INDEX(Items!$J$5:$J$9,4)-IF(Inputs!$B$21="Yes",IF(Inputs!$B$31="Shared",Inputs!$B$32*(Inputs!$B$25+4*ROUNDUP(E$5*Inputs!$B$12*7/Inputs!$B$32/Inputs!$B$24,0)*(Inputs!$B$26+Inputs!$B$27))/60,Inputs!$B$32*4*(Inputs!$B$25+ROUNDUP(E$5*Inputs!$B$12*7/Inputs!$B$32/Inputs!$B$24,0)*(Inputs!$B$26+Inputs!$B$27))/60)*Inputs!$B$30,0))*52 | F10: =(F$5*Inputs!$B$12*7*INDEX(Items!$I$5:$I$9,4)-F$5*Inputs!$B$12*7*INDEX(Items!$J$5:$J$9,4)-IF(Inputs!$B$21="Yes",IF(Inputs!$B$31="Shared",Inputs!$B$32*(Inputs!$B$25+4*ROUNDUP(F$5*Inputs!$B$12*7/Inputs!$B$32/Inputs!$B$24,0)*(Inputs!$B$26+Inputs!$B$27))/60,Inputs!$B$32*4*(Inputs!$B$25+ROUNDUP(F$5*Inputs!$B$12*7/Inputs!$B$32/Inputs!$B$24,0)*(Inputs!$B$26+Inputs!$B$27))/60)*Inputs!$B$30,0))*52 | G10: =(G$5*Inputs!$B$12*7*INDEX(Items!$I$5:$I$9,4)-G$5*Inputs!$B$12*7*INDEX(Items!$J$5:$J$9,4)-IF(Inputs!$B$21="Yes",IF(Inputs!$B$31="Shared",Inputs!$B$32*(Inputs!$B$25+4*ROUNDUP(G$5*Inputs!$B$12*7/Inputs!$B$32/Inputs!$B$24,0)*(Inputs!$B$26+Inputs!$B$27))/60,Inputs!$B$32*4*(Inputs!$B$25+ROUNDUP(G$5*Inputs!$B$12*7/Inputs!$B$32/Inputs!$B$24,0)*(Inputs!$B$26+Inputs!$B$27))/60)*Inputs!$B$30,0))*52
A11: 5 SKUs | B11: =(B$5*Inputs!$B$12*7*INDEX(Items!$I$5:$I$9,5)-B$5*Inputs!$B$12*7*INDEX(Items!$J$5:$J$9,5)-IF(Inputs!$B$21="Yes",IF(Inputs!$B$31="Shared",Inputs!$B$32*(Inputs!$B$25+5*ROUNDUP(B$5*Inputs!$B$12*7/Inputs!$B$32/Inputs!$B$24,0)*(Inputs!$B$26+Inputs!$B$27))/60,Inputs!$B$32*5*(Inputs!$B$25+ROUNDUP(B$5*Inputs!$B$12*7/Inputs!$B$32/Inputs!$B$24,0)*(Inputs!$B$26+Inputs!$B$27))/60)*Inputs!$B$30,0))*52 | C11: =(C$5*Inputs!$B$12*7*INDEX(Items!$I$5:$I$9,5)-C$5*Inputs!$B$12*7*INDEX(Items!$J$5:$J$9,5)-IF(Inputs!$B$21="Yes",IF(Inputs!$B$31="Shared",Inputs!$B$32*(Inputs!$B$25+5*ROUNDUP(C$5*Inputs!$B$12*7/Inputs!$B$32/Inputs!$B$24,0)*(Inputs!$B$26+Inputs!$B$27))/60,Inputs!$B$32*5*(Inputs!$B$25+ROUNDUP(C$5*Inputs!$B$12*7/Inputs!$B$32/Inputs!$B$24,0)*(Inputs!$B$26+Inputs!$B$27))/60)*Inputs!$B$30,0))*52 | D11: =(D$5*Inputs!$B$12*7*INDEX(Items!$I$5:$I$9,5)-D$5*Inputs!$B$12*7*INDEX(Items!$J$5:$J$9,5)-IF(Inputs!$B$21="Yes",IF(Inputs!$B$31="Shared",Inputs!$B$32*(Inputs!$B$25+5*ROUNDUP(D$5*Inputs!$B$12*7/Inputs!$B$32/Inputs!$B$24,0)*(Inputs!$B$26+Inputs!$B$27))/60,Inputs!$B$32*5*(Inputs!$B$25+ROUNDUP(D$5*Inputs!$B$12*7/Inputs!$B$32/Inputs!$B$24,0)*(Inputs!$B$26+Inputs!$B$27))/60)*Inputs!$B$30,0))*52 | E11: =(E$5*Inputs!$B$12*7*INDEX(Items!$I$5:$I$9,5)-E$5*Inputs!$B$12*7*INDEX(Items!$J$5:$J$9,5)-IF(Inputs!$B$21="Yes",IF(Inputs!$B$31="Shared",Inputs!$B$32*(Inputs!$B$25+5*ROUNDUP(E$5*Inputs!$B$12*7/Inputs!$B$32/Inputs!$B$24,0)*(Inputs!$B$26+Inputs!$B$27))/60,Inputs!$B$32*5*(Inputs!$B$25+ROUNDUP(E$5*Inputs!$B$12*7/Inputs!$B$32/Inputs!$B$24,0)*(Inputs!$B$26+Inputs!$B$27))/60)*Inputs!$B$30,0))*52 | F11: =(F$5*Inputs!$B$12*7*INDEX(Items!$I$5:$I$9,5)-F$5*Inputs!$B$12*7*INDEX(Items!$J$5:$J$9,5)-IF(Inputs!$B$21="Yes",IF(Inputs!$B$31="Shared",Inputs!$B$32*(Inputs!$B$25+5*ROUNDUP(F$5*Inputs!$B$12*7/Inputs!$B$32/Inputs!$B$24,0)*(Inputs!$B$26+Inputs!$B$27))/60,Inputs!$B$32*5*(Inputs!$B$25+ROUNDUP(F$5*Inputs!$B$12*7/Inputs!$B$32/Inputs!$B$24,0)*(Inputs!$B$26+Inputs!$B$27))/60)*Inputs!$B$30,0))*52 | G11: =(G$5*Inputs!$B$12*7*INDEX(Items!$I$5:$I$9,5)-G$5*Inputs!$B$12*7*INDEX(Items!$J$5:$J$9,5)-IF(Inputs!$B$21="Yes",IF(Inputs!$B$31="Shared",Inputs!$B$32*(Inputs!$B$25+5*ROUNDUP(G$5*Inputs!$B$12*7/Inputs!$B$32/Inputs!$B$24,0)*(Inputs!$B$26+Inputs!$B$27))/60,Inputs!$B$32*5*(Inputs!$B$25+ROUNDUP(G$5*Inputs!$B$12*7/Inputs!$B$32/Inputs!$B$24,0)*(Inputs!$B$26+Inputs!$B$27))/60)*Inputs!$B$30,0))*52
A13: UNITS PER BAKE SESSION (the number that decides everything)
A14: SKUs | B14: 1 acct | C14: 2 accts | D14: 3 accts | E14: 5 accts | F14: 8 accts | G14: 12 accts
A15: 1 SKU | B15: =1*B$5*Inputs!$B$12*7/Inputs!$B$32 | C15: =1*C$5*Inputs!$B$12*7/Inputs!$B$32 | D15: =1*D$5*Inputs!$B$12*7/Inputs!$B$32 | E15: =1*E$5*Inputs!$B$12*7/Inputs!$B$32 | F15: =1*F$5*Inputs!$B$12*7/Inputs!$B$32 | G15: =1*G$5*Inputs!$B$12*7/Inputs!$B$32 | H15: =" A full batch is "&TEXT(Inputs!$B$24,"0")&" units. Anything not a clean multiple wastes a partial batch's prep and bake time."
A16: 2 SKUs | B16: =2*B$5*Inputs!$B$12*7/Inputs!$B$32 | C16: =2*C$5*Inputs!$B$12*7/Inputs!$B$32 | D16: =2*D$5*Inputs!$B$12*7/Inputs!$B$32 | E16: =2*E$5*Inputs!$B$12*7/Inputs!$B$32 | F16: =2*F$5*Inputs!$B$12*7/Inputs!$B$32 | G16: =2*G$5*Inputs!$B$12*7/Inputs!$B$32
A17: 3 SKUs | B17: =3*B$5*Inputs!$B$12*7/Inputs!$B$32 | C17: =3*C$5*Inputs!$B$12*7/Inputs!$B$32 | D17: =3*D$5*Inputs!$B$12*7/Inputs!$B$32 | E17: =3*E$5*Inputs!$B$12*7/Inputs!$B$32 | F17: =3*F$5*Inputs!$B$12*7/Inputs!$B$32 | G17: =3*G$5*Inputs!$B$12*7/Inputs!$B$32
A18: 4 SKUs | B18: =4*B$5*Inputs!$B$12*7/Inputs!$B$32 | C18: =4*C$5*Inputs!$B$12*7/Inputs!$B$32 | D18: =4*D$5*Inputs!$B$12*7/Inputs!$B$32 | E18: =4*E$5*Inputs!$B$12*7/Inputs!$B$32 | F18: =4*F$5*Inputs!$B$12*7/Inputs!$B$32 | G18: =4*G$5*Inputs!$B$12*7/Inputs!$B$32
A19: 5 SKUs | B19: =5*B$5*Inputs!$B$12*7/Inputs!$B$32 | C19: =5*C$5*Inputs!$B$12*7/Inputs!$B$32 | D19: =5*D$5*Inputs!$B$12*7/Inputs!$B$32 | E19: =5*E$5*Inputs!$B$12*7/Inputs!$B$32 | F19: =5*F$5*Inputs!$B$12*7/Inputs!$B$32 | G19: =5*G$5*Inputs!$B$12*7/Inputs!$B$32
A21: WHAT HERE & THERE ACTUALLY SELLS (measured — your competition on that shelf)
A22: Benchmark | B22: Value | H22: Source
A23: Your madeleine, units/day at LM | B23: 8.7 | H23: Store Sales tab, Aug 1-7 average
A24: Total pastry units/day at LM (est) | B24: 84 | H24: GFS invoice 52 units / 62% GFS share of the mix
A25: GFS SKUs on that invoice | B25: 14 | H25: invoice 1066099707, 07-19-26
A26: Average GFS SKU, units/day | B26: 3.7 | H26: 52 units across 14 SKUs
A27: Best GFS SKU (ham & gruyere) | B27: 10 | H27: the ceiling for one SKU at one cafe
A28: GFS wholesale price range | B28: 4.35 | H28: $2.30 cookie to $4.35 ham & gruyere - your price band
A29: Your wholesale at 50% of $5 | B29: 2.5 | H29: sits inside that band
A31: A single cafe absorbs roughly 3-10 units/day of any one pastry SKU. Five SKUs at one account is therefore ~20-50 units/day total — not enough to fill batches.
A32: The same five SKUs across five accounts is 100-250 units/day on the SAME bake sessions. That is where the money is.

Sheet Capacity
A1: CAPACITY — what a filled week is worth
A2: Drive the model from HOURS instead of volume. You buy kitchen time by the hour, so the real question is what each bake hour produces and whether it clears $80.
A3: =" "&TEXT(Inputs!$B$32,"0")&" sessions/week · batch yield "&TEXT(Inputs!$B$24,"0")&" · "&TEXT(Inputs!$B$26+Inputs!$B$27,"0")&" min per batch · materials $"&TEXT(Inputs!$B$20,"0.00")&"/unit · time $"&TEXT(Inputs!$B$30,"0")&"/hr"
A5: A · THE HOURLY MATH (this one block explains every number below)
A6: Minutes per batch (prep + bake) | B6: =Inputs!$B$26+Inputs!$B$27 | D6: PREP_MIN + BAKE_MIN
A7: Units per batch | B7: =Inputs!$B$24 | D7: BATCH_YIELD
A8: Units produced per bake hour | B8: =60/$B$6*$B$7 | D8: setup excluded — the theoretical rate
A9: Blended wholesale price | B9: =AVERAGE(Items!$C$5:$C$9)*Inputs!$B$14 | D9: Items tab x Inputs!B14
A10: Materials per unit | B10: =Inputs!$B$20 | D10: Flat or Computed per Inputs!B18
A11: Contribution per unit | B11: =$B$9-$B$10 | D11: before any time cost
A12: Gross contribution per bake hour | B12: =$B$8*$B$11 | D12: what an hour of baking earns
A13: Cost of a bake hour | B13: =Inputs!$B$30 | D13: labor + commercial kitchen
A14: NET PROFIT PER BAKE HOUR | B14: =$B$12-$B$13 | D14: if this is negative, no schedule fixes it
A15: =IF($B$14>0,"Every additional bake hour adds $"&TEXT($B$14,"0.00")&" of profit. Fill the schedule.","A bake hour LOSES $"&TEXT(-$B$14,"0.00")&". Filling the schedule multiplies the loss — fix yield, rate, or price first.")
A17: B · WEEKLY SCHEDULE SCENARIOS
A18: SKUs carried | B18: 5 | C18: used only for the accounts-needed column
